Workbook

Sheet JULIO
C2: RESUMEN | E2: VENTA PERIODO | F2: NETO | G2: % COSTO VENTA | M2: OP | N2: 0.25 | O2: 0.06 | P2: 0.12 | Q2: 0.03 | R2: 0.02
C3: COMERCIAL | F3: =E3/1.19 | G3: =(N6+O6)/F3
C4: VENTA ACTUAL | M4: IND | N4: =IF(N5>N2,"MAL","BIEN") | O4: =IF(O5>O2,"MAL","BIEN") | P4: =IF(P5>P2,"MAL","BIEN") | Q4: =IF(Q5>Q2,"MAL","BIEN") | R4: =IF(R5>R2,"MAL","BIEN")
C5: COSTO VENTA | D5: =N6+O6 | G5: 24 horas | H5: IVA | I5: TOTAL | M5: % | N5: =N6/F3 | O5: =O6/$F$3 | P5: =P6/$F$3 | Q5: =Q6/$F$3 | R5: =R6/$F$3
C6: % COSTO VENTA | D6: =D5/(D4/1.19) | F6: TOTAL ITEM | G6: =JULIO!$G$657 | H6: =JULIO!$H$657 | I6: =JULIO!$I$657 | M6: T | N6: =N657 | O6: =O657 | P6: =P657 | Q6: =Q657 | R6: =R657
B8: DIA | C8: NUM INT | D8: TIPO | E8: PROVEEDOR | F8: NUM FACTURA | G8: SUB TOTAL | H8: IVA | I8: TOTAL | J8: DETALLE | K8: MEDIO PAGO | L8: N CHEQUE | N8: AL | O8: BA | P8: GF | Q8: OT | R8: AS | T8: Abel leal Burgos | U8: Agricola Mamita Paz | V8: Agricola rosario | W8: Agrosuper | X8: Alca | Y8: ALMACENES PARIS | Z8: American pos | AA8: Arenillas | AB8: Atelier | AC8: Aurelia Quezada | AD8: Bastien | AE8: Bredenmaster | AF8: Buen chef | AG8: Carnes Ñuble | AH8: CCU | AI8: Cencosud | AJ8: Central Mayorista | AK8: Chokko | AL8: Coca Cola Andina | AM8: Com. Inver. Chacabuco | AN8: Decaba | AO8: DELMAR | AP8: Desa | AQ8: DIMERC | AR8: EASY | AS8: el taller | AT8: Europapel | AU8: FBS | AV8: FEDERAL SEGURIDAD | AW8: FHM Alimentos | AX8: Fortunata | AY8: Gazpacho | AZ8: Global Frozen | BA8: Gourmet virtual | BB8: Granarolo | BC8: Guallarauco | BD8: Hielo freeze | BE8: Indusmel | BF8: Inversierra | BG8: Isla del faraon | BH8: Jaime Cesar Farias | BI8: Jose Molina | BJ8: Julia del Carmen | BK8: JUMBO | BL8: KITCHEN CENTER SPA | BM8: La Isla del Faraon | BN8: La Vaquita | BO8: La Vinoteca | BP8: Las Delicias del | BQ8: Las piedras | BR8: licores.cl | BS8: Limpicamp Ltda. | BT8: Los colonos | BU8: Mauro | BV8: Mercado Silvestre | BW8: Miguel | BX8: MIGUEL ANGEL PARRA | BY8: Miguel Gonzalez | BZ8: Mimus | CA8: Modus Vivendi | CB8: Neuchatel S.A. | CC8: Nubox | CD8: P&E | CE8: Pahuilmo | CF8: Palta Mundial | CG8: Panesco | CH8: Papeles Santiago | CI8: PC FACTORY | CJ8: Pedidos de hoy | CK8: Pest free | CL8: PF | CM8: Premium Brands | CN8: Productos galdames | CO8: Punto entrega | CP8: PUNTO PLAST | CQ8: RENATE IWERSEN | CR8: Saint Jacques | CS8: Santa Rita | CT8: Servicefood | CU8: silvestre | CV8: Sociedad agricola | CW8: Sofruco | CX8: Southwind | CY8: SURA | CZ8: Surlat | DA8: VCT
G9: =JULIO!$I9-JULIO!$H9 | N9: =IF($D9="AL",$G9,0) | O9: =IF($D9="BA",$G9,0) | P9: =IF($D9="GF",$G9,0) | Q9: =IF($D9="OT",$G9,0) | R9: =IF($D9="AS",$G9,0) | T9: =IF($E9=T$8,$G9,0) | U9: =IF($E9=U$8,$G9,0) | V9: =IF($E9=V$8,$G9,0) | W9: =IF($E9=W$8,$G9,0) | X9: =IF($E9=X$8,$G9,0) | Y9: =IF($E9=Y$8,$G9,0) | Z9: =IF($E9=Z$8,$G9,0) | AA9: =IF($E9=AA$8,$G9,0) | ... DA9: =IF($E9=DA$8,$G9,0)
G10: =JULIO!$I10-JULIO!$H10 | N10: =IF($D10="AL",$G10,0) | O10: =IF($D10="BA",$G10,0) | P10: =IF($D10="GF",$G10,0) | Q10: =IF($D10="OT",$G10,0) | R10: =IF($D10="AS",$G10,0) | T10: =IF($E10=T$8,$G10,0) | U10: =IF($E10=U$8,$G10,0) | V10: =IF($E10=V$8,$G10,0) | W10: =IF($E10=W$8,$G10,0) | X10: =IF($E10=X$8,$G10,0) | Y10: =IF($E10=Y$8,$G10,0) | Z10: =IF($E10=Z$8,$G10,0) | AA10: =IF($E10=AA$8,$G10,0) | ... DA10: =IF($E10=DA$8,$G10,0)
G11: =JULIO!$I11-JULIO!$H11 | N11: =IF($D11="AL",$G11,0) | O11: =IF($D11="BA",$G11,0) | P11: =IF($D11="GF",$G11,0) | Q11: =IF($D11="OT",$G11,0) | R11: =IF($D11="AS",$G11,0) | T11: =IF($E11=T$8,$G11,0) | U11: =IF($E11=U$8,$G11,0) | V11: =IF($E11=V$8,$G11,0) | W11: =IF($E11=W$8,$G11,0) | X11: =IF($E11=X$8,$G11,0) | Y11: =IF($E11=Y$8,$G11,0) | Z11: =IF($E11=Z$8,$G11,0) | AA11: =IF($E11=AA$8,$G11,0) | ... DA11: =IF($E11=DA$8,$G11,0)
G12: =JULIO!$I12-JULIO!$H12 | N12: =IF($D12="AL",$G12,0) | O12: =IF($D12="BA",$G12,0) | P12: =IF($D12="GF",$G12,0) | Q12: =IF($D12="OT",$G12,0) | R12: =IF($D12="AS",$G12,0) | T12: =IF($E12=T$8,$G12,0) | U12: =IF($E12=U$8,$G12,0) | V12: =IF($E12=V$8,$G12,0) | W12: =IF($E12=W$8,$G12,0) | X12: =IF($E12=X$8,$G12,0) | Y12: =IF($E12=Y$8,$G12,0) | Z12: =IF($E12=Z$8,$G12,0) | AA12: =IF($E12=AA$8,$G12,0) | ... DA12: =IF($E12=DA$8,$G12,0)
G13: =JULIO!$I13-JULIO!$H13 | N13: =IF($D13="AL",$G13,0) | O13: =IF($D13="BA",$G13,0) | P13: =IF($D13="GF",$G13,0) | Q13: =IF($D13="OT",$G13,0) | R13: =IF($D13="AS",$G13,0) | T13: =IF($E13=T$8,$G13,0) | U13: =IF($E13=U$8,$G13,0) | V13: =IF($E13=V$8,$G13,0) | W13: =IF($E13=W$8,$G13,0) | X13: =IF($E13=X$8,$G13,0) | Y13: =IF($E13=Y$8,$G13,0) | Z13: =IF($E13=Z$8,$G13,0) | AA13: =IF($E13=AA$8,$G13,0) | ... DA13: =IF($E13=DA$8,$G13,0)
G14: =JULIO!$I14-JULIO!$H14 | N14: =IF($D14="AL",$G14,0) | O14: =IF($D14="BA",$G14,0) | P14: =IF($D14="GF",$G14,0) | Q14: =IF($D14="OT",$G14,0) | R14: =IF($D14="AS",$G14,0) | T14: =IF($E14=T$8,$G14,0) | U14: =IF($E14=U$8,$G14,0) | V14: =IF($E14=V$8,$G14,0) | W14: =IF($E14=W$8,$G14,0) | X14: =IF($E14=X$8,$G14,0) | Y14: =IF($E14=Y$8,$G14,0) | Z14: =IF($E14=Z$8,$G14,0) | AA14: =IF($E14=AA$8,$G14,0) | ... DA14: =IF($E14=DA$8,$G14,0)
G15: =JULIO!$I15-JULIO!$H15 | N15: =IF($D15="AL",$G15,0) | O15: =IF($D15="BA",$G15,0) | P15: =IF($D15="GF",$G15,0) | Q15: =IF($D15="OT",$G15,0) | R15: =IF($D15="AS",$G15,0) | T15: =IF($E15=T$8,$G15,0) | U15: =IF($E15=U$8,$G15,0) | V15: =IF($E15=V$8,$G15,0) | W15: =IF($E15=W$8,$G15,0) | X15: =IF($E15=X$8,$G15,0) | Y15: =IF($E15=Y$8,$G15,0) | Z15: =IF($E15=Z$8,$G15,0) | AA15: =IF($E15=AA$8,$G15,0) | ... DA15: =IF($E15=DA$8,$G15,0)
G16: =JULIO!$I16-JULIO!$H16 | N16: =IF($D16="AL",$G16,0) | O16: =IF($D16="BA",$G16,0) | P16: =IF($D16="GF",$G16,0) | Q16: =IF($D16="OT",$G16,0) | R16: =IF($D16="AS",$G16,0) | T16: =IF($E16=T$8,$G16,0) | U16: =IF($E16=U$8,$G16,0) | V16: =IF($E16=V$8,$G16,0) | W16: =IF($E16=W$8,$G16,0) | X16: =IF($E16=X$8,$G16,0) | Y16: =IF($E16=Y$8,$G16,0) | Z16: =IF($E16=Z$8,$G16,0) | AA16: =IF($E16=AA$8,$G16,0) | ... DA16: =IF($E16=DA$8,$G16,0)
G17: =JULIO!$I17-JULIO!$H17 | N17: =IF($D17="AL",$G17,0) | O17: =IF($D17="BA",$G17,0) | P17: =IF($D17="GF",$G17,0) | Q17: =IF($D17="OT",$G17,0) | R17: =IF($D17="AS",$G17,0) | T17: =IF($E17=T$8,$G17,0) | U17: =IF($E17=U$8,$G17,0) | V17: =IF($E17=V$8,$G17,0) | W17: =IF($E17=W$8,$G17,0) | X17: =IF($E17=X$8,$G17,0) | Y17: =IF($E17=Y$8,$G17,0) | Z17: =IF($E17=Z$8,$G17,0) | AA17: =IF($E17=AA$8,$G17,0) | ... DA17: =IF($E17=DA$8,$G17,0)
G18: =JULIO!$I18-JULIO!$H18 | N18: =IF($D18="AL",$G18,0) | O18: =IF($D18="BA",$G18,0) | P18: =IF($D18="GF",$G18,0) | Q18: =IF($D18="OT",$G18,0) | R18: =IF($D18="AS",$G18,0) | T18: =IF($E18=T$8,$G18,0) | U18: =IF($E18=U$8,$G18,0) | V18: =IF($E18=V$8,$G18,0) | W18: =IF($E18=W$8,$G18,0) | X18: =IF($E18=X$8,$G18,0) | Y18: =IF($E18=Y$8,$G18,0) | Z18: =IF($E18=Z$8,$G18,0) | AA18: =IF($E18=AA$8,$G18,0) | ... DA18: =IF($E18=DA$8,$G18,0)
G19: =JULIO!$I19-JULIO!$H19 | N19: =IF($D19="AL",$G19,0) | O19: =IF($D19="BA",$G19,0) | P19: =IF($D19="GF",$G19,0) | Q19: =IF($D19="OT",$G19,0) | R19: =IF($D19="AS",$G19,0) | T19: =IF($E19=T$8,$G19,0) | U19: =IF($E19=U$8,$G19,0) | V19: =IF($E19=V$8,$G19,0) | W19: =IF($E19=W$8,$G19,0) | X19: =IF($E19=X$8,$G19,0) | Y19: =IF($E19=Y$8,$G19,0) | Z19: =IF($E19=Z$8,$G19,0) | AA19: =IF($E19=AA$8,$G19,0) | ... DA19: =IF($E19=DA$8,$G19,0)
G20: =JULIO!$I20-JULIO!$H20 | N20: =IF($D20="AL",$G20,0) | O20: =IF($D20="BA",$G20,0) | P20: =IF($D20="GF",$G20,0) | Q20: =IF($D20="OT",$G20,0) | R20: =IF($D20="AS",$G20,0) | T20: =IF($E20=T$8,$G20,0) | U20: =IF($E20=U$8,$G20,0) | V20: =IF($E20=V$8,$G20,0) | W20: =IF($E20=W$8,$G20,0) | X20: =IF($E20=X$8,$G20,0) | Y20: =IF($E20=Y$8,$G20,0) | Z20: =IF($E20=Z$8,$G20,0) | AA20: =IF($E20=AA$8,$G20,0) | ... DA20: =IF($E20=DA$8,$G20,0)
... G172: =JULIO!$I172-JULIO!$H172 | N172: =IF($D172="AL",$G172,0) | O172: =IF($D172="BA",$G172,0) | P172: =IF($D172="GF",$G172,0) | Q172: =IF($D172="OT",$G172,0) | R172: =IF($D172="AS",$G172,0) | T172: =IF($E172=T$8,$G172,0) | U172: =IF($E172=U$8,$G172,0) | V172: =IF($E172=V$8,$G172,0) | W172: =IF($E172=W$8,$G172,0) | X172: =IF($E172=X$8,$G172,0) | Y172: =IF($E172=Y$8,$G172,0) | Z172: =IF($E172=Z$8,$G172,0) | AA172: =IF($E172=AA$8,$G172,0) | ... DA172: =IF($E172=DA$8,$G172,0)
G173: =JULIO!$I173-JULIO!$H173 | K173: OSTIONES | N173: =IF($D173="AL",$G173,0) | O173: =IF($D173="BA",$G173,0) | P173: =IF($D173="GF",$G173,0) | Q173: =IF($D173="OT",$G173,0) | R173: =IF($D173="AS",$G173,0) | T173: =IF($E173=T$8,$G173,0) | U173: =IF($E173=U$8,$G173,0) | V173: =IF($E173=V$8,$G173,0) | W173: =IF($E173=W$8,$G173,0) | X173: =IF($E173=X$8,$G173,0) | Y173: =IF($E173=Y$8,$G173,0) | Z173: =IF($E173=Z$8,$G173,0) | AA173: =IF($E173=AA$8,$G173,0) | ... DA173: =IF($E173=DA$8,$G173,0)
G174: =JULIO!$I174-JULIO!$H174 | N174: =IF($D174="AL",$G174,0) | O174: =IF($D174="BA",$G174,0) | P174: =IF($D174="GF",$G174,0) | Q174: =IF($D174="OT",$G174,0) | R174: =IF($D174="AS",$G174,0) | T174: =IF($E174=T$8,$G174,0) | U174: =IF($E174=U$8,$G174,0) | V174: =IF($E174=V$8,$G174,0) | W174: =IF($E174=W$8,$G174,0) | X174: =IF($E174=X$8,$G174,0) | Y174: =IF($E174=Y$8,$G174,0) | Z174: =IF($E174=Z$8,$G174,0) | AA174: =IF($E174=AA$8,$G174,0) | ... DA174: =IF($E174=DA$8,$G174,0)
G175: =JULIO!$I175-JULIO!$H175 | N175: =IF($D175="AL",$G175,0) | O175: =IF($D175="BA",$G175,0) | P175: =IF($D175="GF",$G175,0) | Q175: =IF($D175="OT",$G175,0) | R175: =IF($D175="AS",$G175,0) | T175: =IF($E175=T$8,$G175,0) | U175: =IF($E175=U$8,$G175,0) | V175: =IF($E175=V$8,$G175,0) | W175: =IF($E175=W$8,$G175,0) | X175: =IF($E175=X$8,$G175,0) | Y175: =IF($E175=Y$8,$G175,0) | Z175: =IF($E175=Z$8,$G175,0) | AA175: =IF($E175=AA$8,$G175,0) | ... DA175: =IF($E175=DA$8,$G175,0)
G176: =JULIO!$I176-JULIO!$H176 | N176: =IF($D176="AL",$G176,0) | O176: =IF($D176="BA",$G176,0) | P176: =IF($D176="GF",$G176,0) | Q176: =IF($D176="OT",$G176,0) | R176: =IF($D176="AS",$G176,0) | T176: =IF($E176=T$8,$G176,0) | U176: =IF($E176=U$8,$G176,0) | V176: =IF($E176=V$8,$G176,0) | W176: =IF($E176=W$8,$G176,0) | X176: =IF($E176=X$8,$G176,0) | Y176: =IF($E176=Y$8,$G176,0) | Z176: =IF($E176=Z$8,$G176,0) | AA176: =IF($E176=AA$8,$G176,0) | ... DA176: =IF($E176=DA$8,$G176,0)
G177: =JULIO!$I177-JULIO!$H177 | N177: =IF($D177="AL",$G177,0) | O177: =IF($D177="BA",$G177,0) | P177: =IF($D177="GF",$G177,0) | Q177: =IF($D177="OT",$G177,0) | R177: =IF($D177="AS",$G177,0) | T177: =IF($E177=T$8,$G177,0) | U177: =IF($E177=U$8,$G177,0) | V177: =IF($E177=V$8,$G177,0) | W177: =IF($E177=W$8,$G177,0) | X177: =IF($E177=X$8,$G177,0) | Y177: =IF($E177=Y$8,$G177,0) | Z177: =IF($E177=Z$8,$G177,0) | AA177: =IF($E177=AA$8,$G177,0) | ... DA177: =IF($E177=DA$8,$G177,0)
G178: =JULIO!$I178-JULIO!$H178 | N178: =IF($D178="AL",$G178,0) | O178: =IF($D178="BA",$G178,0) | P178: =IF($D178="GF",$G178,0) | Q178: =IF($D178="OT",$G178,0) | R178: =IF($D178="AS",$G178,0) | T178: =IF($E178=T$8,$G178,0) | U178: =IF($E178=U$8,$G178,0) | V178: =IF($E178=V$8,$G178,0) | W178: =IF($E178=W$8,$G178,0) | X178: =IF($E178=X$8,$G178,0) | Y178: =IF($E178=Y$8,$G178,0) | Z178: =IF($E178=Z$8,$G178,0) | AA178: =IF($E178=AA$8,$G178,0) | ... DA178: =IF($E178=DA$8,$G178,0)
G179: =JULIO!$I179-JULIO!$H179 | N179: =IF($D179="AL",$G179,0) | O179: =IF($D179="BA",$G179,0) | P179: =IF($D179="GF",$G179,0) | Q179: =IF($D179="OT",$G179,0) | R179: =IF($D179="AS",$G179,0) | T179: =IF($E179=T$8,$G179,0) | U179: =IF($E179=U$8,$G179,0) | V179: =IF($E179=V$8,$G179,0) | W179: =IF($E179=W$8,$G179,0) | X179: =IF($E179=X$8,$G179,0) | Y179: =IF($E179=Y$8,$G179,0) | Z179: =IF($E179=Z$8,$G179,0) | AA179: =IF($E179=AA$8,$G179,0) | ... DA179: =IF($E179=DA$8,$G179,0)
G180: =JULIO!$I180-JULIO!$H180 | N180: =IF($D180="AL",$G180,0) | O180: =IF($D180="BA",$G180,0) | P180: =IF($D180="GF",$G180,0) | Q180: =IF($D180="OT",$G180,0) | R180: =IF($D180="AS",$G180,0) | T180: =IF($E180=T$8,$G180,0) | U180: =IF($E180=U$8,$G180,0) | V180: =IF($E180=V$8,$G180,0) | W180: =IF($E180=W$8,$G180,0) | X180: =IF($E180=X$8,$G180,0) | Y180: =IF($E180=Y$8,$G180,0) | Z180: =IF($E180=Z$8,$G180,0) | AA180: =IF($E180=AA$8,$G180,0) | ... DA180: =IF($E180=DA$8,$G180,0)
G181: =JULIO!$I181-JULIO!$H181 | N181: =IF($D181="AL",$G181,0) | O181: =IF($D181="BA",$G181,0) | P181: =IF($D181="GF",$G181,0) | Q181: =IF($D181="OT",$G181,0) | R181: =IF($D181="AS",$G181,0) | T181: =IF($E181=T$8,$G181,0) | U181: =IF($E181=U$8,$G181,0) | V181: =IF($E181=V$8,$G181,0) | W181: =IF($E181=W$8,$G181,0) | X181: =IF($E181=X$8,$G181,0) | Y181: =IF($E181=Y$8,$G181,0) | Z181: =IF($E181=Z$8,$G181,0) | AA181: =IF($E181=AA$8,$G181,0) | ... DA181: =IF($E181=DA$8,$G181,0)
G182: =JULIO!$I182-JULIO!$H182 | N182: =IF($D182="AL",$G182,0) | O182: =IF($D182="BA",$G182,0) | P182: =IF($D182="GF",$G182,0) | Q182: =IF($D182="OT",$G182,0) | R182: =IF($D182="AS",$G182,0) | T182: =IF($E182=T$8,$G182,0) | U182: =IF($E182=U$8,$G182,0) | V182: =IF($E182=V$8,$G182,0) | W182: =IF($E182=W$8,$G182,0) | X182: =IF($E182=X$8,$G182,0) | Y182: =IF($E182=Y$8,$G182,0) | Z182: =IF($E182=Z$8,$G182,0) | AA182: =IF($E182=AA$8,$G182,0) | ... DA182: =IF($E182=DA$8,$G182,0)
G183: =JULIO!$I183-JULIO!$H183 | N183: =IF($D183="AL",$G183,0) | O183: =IF($D183="BA",$G183,0) | P183: =IF($D183="GF",$G183,0) | Q183: =IF($D183="OT",$G183,0) | R183: =IF($D183="AS",$G183,0) | T183: =IF($E183=T$8,$G183,0) | U183: =IF($E183=U$8,$G183,0) | V183: =IF($E183=V$8,$G183,0) | W183: =IF($E183=W$8,$G183,0) | X183: =IF($E183=X$8,$G183,0) | Y183: =IF($E183=Y$8,$G183,0) | Z183: =IF($E183=Z$8,$G183,0) | AA183: =IF($E183=AA$8,$G183,0) | ... DA183: =IF($E183=DA$8,$G183,0)
G184: =JULIO!$I184-JULIO!$H184 | N184: =IF($D184="AL",$G184,0) | O184: =IF($D184="BA",$G184,0) | P184: =IF($D184="GF",$G184,0) | Q184: =IF($D184="OT",$G184,0) | R184: =IF($D184="AS",$G184,0) | T184: =IF($E184=T$8,$G184,0) | U184: =IF($E184=U$8,$G184,0) | V184: =IF($E184=V$8,$G184,0) | W184: =IF($E184=W$8,$G184,0) | X184: =IF($E184=X$8,$G184,0) | Y184: =IF($E184=Y$8,$G184,0) | Z184: =IF($E184=Z$8,$G184,0) | AA184: =IF($E184=AA$8,$G184,0) | ... DA184: =IF($E184=DA$8,$G184,0)
G185: =JULIO!$I185-JULIO!$H185 | N185: =IF($D185="AL",$G185,0) | O185: =IF($D185="BA",$G185,0) | P185: =IF($D185="GF",$G185,0) | Q185: =IF($D185="OT",$G185,0) | R185: =IF($D185="AS",$G185,0) | T185: =IF($E185=T$8,$G185,0) | U185: =IF($E185=U$8,$G185,0) | V185: =IF($E185=V$8,$G185,0) | W185: =IF($E185=W$8,$G185,0) | X185: =IF($E185=X$8,$G185,0) | Y185: =IF($E185=Y$8,$G185,0) | Z185: =IF($E185=Z$8,$G185,0) | AA185: =IF($E185=AA$8,$G185,0) | ... DA185: =IF($E185=DA$8,$G185,0)
... G201: =JULIO!$I201-JULIO!$H201 | N201: =IF($D201="AL",$G201,0) | O201: =IF($D201="BA",$G201,0) | P201: =IF($D201="GF",$G201,0) | Q201: =IF($D201="OT",$G201,0) | R201: =IF($D201="AS",$G201,0) | T201: =IF($E201=T$8,$G201,0) | U201: =IF($E201=U$8,$G201,0) | V201: =IF($E201=V$8,$G201,0) | W201: =IF($E201=W$8,$G201,0) | X201: =IF($E201=X$8,$G201,0) | Y201: =IF($E201=Y$8,$G201,0) | Z201: =IF($E201=Z$8,$G201,0) | AA201: =IF($E201=AA$8,$G201,0) | ... DA201: =IF($E201=DA$8,$G201,0)
G202: =JULIO!$I202-JULIO!$H202 | J202: a | N202: =IF($D202="AL",$G202,0) | O202: =IF($D202="BA",$G202,0) | P202: =IF($D202="GF",$G202,0) | Q202: =IF($D202="OT",$G202,0) | R202: =IF($D202="AS",$G202,0) | T202: =IF($E202=T$8,$G202,0) | U202: =IF($E202=U$8,$G202,0) | V202: =IF($E202=V$8,$G202,0) | W202: =IF($E202=W$8,$G202,0) | X202: =IF($E202=X$8,$G202,0) | Y202: =IF($E202=Y$8,$G202,0) | Z202: =IF($E202=Z$8,$G202,0) | AA202: =IF($E202=AA$8,$G202,0) | ... DA202: =IF($E202=DA$8,$G202,0)
G203: =JULIO!$I203-JULIO!$H203 | N203: =IF($D203="AL",$G203,0) | O203: =IF($D203="BA",$G203,0) | P203: =IF($D203="GF",$G203,0) | Q203: =IF($D203="OT",$G203,0) | R203: =IF($D203="AS",$G203,0) | T203: =IF($E203=T$8,$G203,0) | U203: =IF($E203=U$8,$G203,0) | V203: =IF($E203=V$8,$G203,0) | W203: =IF($E203=W$8,$G203,0) | X203: =IF($E203=X$8,$G203,0) | Y203: =IF($E203=Y$8,$G203,0) | Z203: =IF($E203=Z$8,$G203,0) | AA203: =IF($E203=AA$8,$G203,0) | ... DA203: =IF($E203=DA$8,$G203,0)
G204: =JULIO!$I204-JULIO!$H204 | N204: =IF($D204="AL",$G204,0) | O204: =IF($D204="BA",$G204,0) | P204: =IF($D204="GF",$G204,0) | Q204: =IF($D204="OT",$G204,0) | R204: =IF($D204="AS",$G204,0) | T204: =IF($E204=T$8,$G204,0) | U204: =IF($E204=U$8,$G204,0) | V204: =IF($E204=V$8,$G204,0) | W204: =IF($E204=W$8,$G204,0) | X204: =IF($E204=X$8,$G204,0) | Y204: =IF($E204=Y$8,$G204,0) | Z204: =IF($E204=Z$8,$G204,0) | AA204: =IF($E204=AA$8,$G204,0) | ... DA204: =IF($E204=DA$8,$G204,0)
G205: =JULIO!$I205-JULIO!$H205 | N205: =IF($D205="AL",$G205,0) | O205: =IF($D205="BA",$G205,0) | P205: =IF($D205="GF",$G205,0) | Q205: =IF($D205="OT",$G205,0) | R205: =IF($D205="AS",$G205,0) | T205: =IF($E205=T$8,$G205,0) | U205: =IF($E205=U$8,$G205,0) | V205: =IF($E205=V$8,$G205,0) | W205: =IF($E205=W$8,$G205,0) | X205: =IF($E205=X$8,$G205,0) | Y205: =IF($E205=Y$8,$G205,0) | Z205: =IF($E205=Z$8,$G205,0) | AA205: =IF($E205=AA$8,$G205,0) | ... DA205: =IF($E205=DA$8,$G205,0)
G206: =JULIO!$I206-JULIO!$H206 | N206: =IF($D206="AL",$G206,0) | O206: =IF($D206="BA",$G206,0) | P206: =IF($D206="GF",$G206,0) | Q206: =IF($D206="OT",$G206,0) | R206: =IF($D206="AS",$G206,0) | T206: =IF($E206=T$8,$G206,0) | U206: =IF($E206=U$8,$G206,0) | V206: =IF($E206=V$8,$G206,0) | W206: =IF($E206=W$8,$G206,0) | X206: =IF($E206=X$8,$G206,0) | Y206: =IF($E206=Y$8,$G206,0) | Z206: =IF($E206=Z$8,$G206,0) | AA206: =IF($E206=AA$8,$G206,0) | ... DA206: =IF($E206=DA$8,$G206,0)
G207: =JULIO!$I207-JULIO!$H207 | N207: =IF($D207="AL",$G207,0) | O207: =IF($D207="BA",$G207,0) | P207: =IF($D207="GF",$G207,0) | Q207: =IF($D207="OT",$G207,0) | R207: =IF($D207="AS",$G207,0) | T207: =IF($E207=T$8,$G207,0) | U207: =IF($E207=U$8,$G207,0) | V207: =IF($E207=V$8,$G207,0) | W207: =IF($E207=W$8,$G207,0) | X207: =IF($E207=X$8,$G207,0) | Y207: =IF($E207=Y$8,$G207,0) | Z207: =IF($E207=Z$8,$G207,0) | AA207: =IF($E207=AA$8,$G207,0) | ... DA207: =IF($E207=DA$8,$G207,0)
G208: =JULIO!$I208-JULIO!$H208 | N208: =IF($D208="AL",$G208,0) | O208: =IF($D208="BA",$G208,0) | P208: =IF($D208="GF",$G208,0) | Q208: =IF($D208="OT",$G208,0) | R208: =IF($D208="AS",$G208,0) | T208: =IF($E208=T$8,$G208,0) | U208: =IF($E208=U$8,$G208,0) | V208: =IF($E208=V$8,$G208,0) | W208: =IF($E208=W$8,$G208,0) | X208: =IF($E208=X$8,$G208,0) | Y208: =IF($E208=Y$8,$G208,0) | Z208: =IF($E208=Z$8,$G208,0) | AA208: =IF($E208=AA$8,$G208,0) | ... DA208: =IF($E208=DA$8,$G208,0)
...
