Workbook

Sheet JUNIO
C2: RESUMEN | E2: VENTA PERIODO | F2: NETO | G2: % COSTO VENTA | M2: OP | N2: 0.25 | O2: 0.06 | P2: 0.12 | Q2: 0.03 | R2: 0.02
C3: COMERCIAL | F3: =E3/1.19 | G3: =(N6+O6)/F3
C4: VENTA ACTUAL | M4: IND | N4: =IF(N5>N2,"MAL","BIEN") | O4: =IF(O5>O2,"MAL","BIEN") | P4: =IF(P5>P2,"MAL","BIEN") | Q4: =IF(Q5>Q2,"MAL","BIEN") | R4: =IF(R5>R2,"MAL","BIEN")
C5: COSTO VENTA | D5: =N6+O6 | G5: 24 horas | H5: IVA | I5: TOTAL | M5: % | N5: =N6/F3 | O5: =O6/$F$3 | P5: =P6/$F$3 | Q5: =Q6/$F$3 | R5: =R6/$F$3
C6: % COSTO VENTA | D6: =D5/(D4/1.19) | F6: TOTAL ITEM | G6: =JUNIO!$G$657 | H6: =JUNIO!$H$657 | I6: =JUNIO!$I$657 | M6: T | N6: =N657 | O6: =O657 | P6: =P657 | Q6: =Q657 | R6: =R657
B8: DIA | C8: NUM INT | D8: TIPO | E8: PROVEEDOR | F8: NUM FACTURA | G8: SUB TOTAL | H8: IVA | I8: TOTAL | J8: DETALLE | K8: MEDIO PAGO | L8: N CHEQUE | N8: AL | O8: BA | P8: GF | Q8: OT | R8: AS | T8: Abel leal Burgos | U8: Agricola Mamita Paz | V8: Agricola rosario | W8: Agrosuper | X8: Alca | Y8: ALMACENES PARIS | Z8: American pos | AA8: Arenillas | AB8: Atelier | AC8: Aurelia Quezada | AD8: Bastien | AE8: Bredenmaster | AF8: Buen chef | AG8: Carnes Ñuble | AH8: CCU | AI8: Cencosud | AJ8: Central Mayorista | AK8: Chokko | AL8: Coca Cola Andina | AM8: Com. Inver. Chacabuco | AN8: Decaba | AO8: DELMAR | AP8: Desa | AQ8: DIMERC | AR8: EASY | AS8: el taller | AT8: Europapel | AU8: FBS | AV8: FEDERAL SEGURIDAD | AW8: FHM Alimentos | AX8: Fortunata | AY8: Gazpacho | AZ8: Global Frozen | BA8: Gourmet virtual | BB8: Granarolo | BC8: Guallarauco | BD8: Hielo freeze | BE8: Indusmel | BF8: Inversierra | BG8: Isla del faraon | BH8: Jaime Cesar Farias | BI8: Jose Molina | BJ8: Julia del Carmen | BK8: JUMBO | BL8: KITCHEN CENTER SPA | BM8: La Isla del Faraon | BN8: La Vaquita | BO8: La Vinoteca | BP8: Las Delicias del | BQ8: Las piedras | BR8: licores.cl | BS8: Limpicamp Ltda. | BT8: Los colonos | BU8: Mauro | BV8: Mercado Silvestre | BW8: Miguel | BX8: MIGUEL ANGEL PARRA | BY8: Miguel Gonzalez | BZ8: Mimus | CA8: Modus Vivendi | CB8: Neuchatel S.A. | CC8: Nubox | CD8: P&E | CE8: Pahuilmo | CF8: Palta Mundial | CG8: Panesco | CH8: Papeles Santiago | CI8: PC FACTORY | CJ8: Pedidos de hoy | CK8: Pest free | CL8: PF | CM8: Premium Brands | CN8: Productos galdames | CO8: Punto entrega | CP8: PUNTO PLAST | CQ8: RENATE IWERSEN | CR8: Saint Jacques | CS8: Santa Rita | CT8: Servicefood | CU8: silvestre | CV8: Sociedad agricola | CW8: Sofruco | CX8: Southwind | CY8: SURA | CZ8: Surlat | DA8: VCT
G9: =JUNIO!$I9-JUNIO!$H9 | N9: =IF($D9="AL",$G9,0) | O9: =IF($D9="BA",$G9,0) | P9: =IF($D9="GF",$G9,0) | Q9: =IF($D9="OT",$G9,0) | R9: =IF($D9="AS",$G9,0) | T9: =IF($E9=T$8,$G9,0) | U9: =IF($E9=U$8,$G9,0) | V9: =IF($E9=V$8,$G9,0) | W9: =IF($E9=W$8,$G9,0) | X9: =IF($E9=X$8,$G9,0) | Y9: =IF($E9=Y$8,$G9,0) | Z9: =IF($E9=Z$8,$G9,0) | AA9: =IF($E9=AA$8,$G9,0) | ... DA9: =IF($E9=DA$8,$G9,0)
G10: =JUNIO!$I10-JUNIO!$H10 | N10: =IF($D10="AL",$G10,0) | O10: =IF($D10="BA",$G10,0) | P10: =IF($D10="GF",$G10,0) | Q10: =IF($D10="OT",$G10,0) | R10: =IF($D10="AS",$G10,0) | T10: =IF($E10=T$8,$G10,0) | U10: =IF($E10=U$8,$G10,0) | V10: =IF($E10=V$8,$G10,0) | W10: =IF($E10=W$8,$G10,0) | X10: =IF($E10=X$8,$G10,0) | Y10: =IF($E10=Y$8,$G10,0) | Z10: =IF($E10=Z$8,$G10,0) | AA10: =IF($E10=AA$8,$G10,0) | ... DA10: =IF($E10=DA$8,$G10,0)
G11: =JUNIO!$I11-JUNIO!$H11 | N11: =IF($D11="AL",$G11,0) | O11: =IF($D11="BA",$G11,0) | P11: =IF($D11="GF",$G11,0) | Q11: =IF($D11="OT",$G11,0) | R11: =IF($D11="AS",$G11,0) | T11: =IF($E11=T$8,$G11,0) | U11: =IF($E11=U$8,$G11,0) | V11: =IF($E11=V$8,$G11,0) | W11: =IF($E11=W$8,$G11,0) | X11: =IF($E11=X$8,$G11,0) | Y11: =IF($E11=Y$8,$G11,0) | Z11: =IF($E11=Z$8,$G11,0) | AA11: =IF($E11=AA$8,$G11,0) | ... DA11: =IF($E11=DA$8,$G11,0)
G12: =JUNIO!$I12-JUNIO!$H12 | N12: =IF($D12="AL",$G12,0) | O12: =IF($D12="BA",$G12,0) | P12: =IF($D12="GF",$G12,0) | Q12: =IF($D12="OT",$G12,0) | R12: =IF($D12="AS",$G12,0) | T12: =IF($E12=T$8,$G12,0) | U12: =IF($E12=U$8,$G12,0) | V12: =IF($E12=V$8,$G12,0) | W12: =IF($E12=W$8,$G12,0) | X12: =IF($E12=X$8,$G12,0) | Y12: =IF($E12=Y$8,$G12,0) | Z12: =IF($E12=Z$8,$G12,0) | AA12: =IF($E12=AA$8,$G12,0) | ... DA12: =IF($E12=DA$8,$G12,0)
G13: =JUNIO!$I13-JUNIO!$H13 | N13: =IF($D13="AL",$G13,0) | O13: =IF($D13="BA",$G13,0) | P13: =IF($D13="GF",$G13,0) | Q13: =IF($D13="OT",$G13,0) | R13: =IF($D13="AS",$G13,0) | T13: =IF($E13=T$8,$G13,0) | U13: =IF($E13=U$8,$G13,0) | V13: =IF($E13=V$8,$G13,0) | W13: =IF($E13=W$8,$G13,0) | X13: =IF($E13=X$8,$G13,0) | Y13: =IF($E13=Y$8,$G13,0) | Z13: =IF($E13=Z$8,$G13,0) | AA13: =IF($E13=AA$8,$G13,0) | ... DA13: =IF($E13=DA$8,$G13,0)
G14: =JUNIO!$I14-JUNIO!$H14 | N14: =IF($D14="AL",$G14,0) | O14: =IF($D14="BA",$G14,0) | P14: =IF($D14="GF",$G14,0) | Q14: =IF($D14="OT",$G14,0) | R14: =IF($D14="AS",$G14,0) | T14: =IF($E14=T$8,$G14,0) | U14: =IF($E14=U$8,$G14,0) | V14: =IF($E14=V$8,$G14,0) | W14: =IF($E14=W$8,$G14,0) | X14: =IF($E14=X$8,$G14,0) | Y14: =IF($E14=Y$8,$G14,0) | Z14: =IF($E14=Z$8,$G14,0) | AA14: =IF($E14=AA$8,$G14,0) | ... DA14: =IF($E14=DA$8,$G14,0)
G15: =JUNIO!$I15-JUNIO!$H15 | N15: =IF($D15="AL",$G15,0) | O15: =IF($D15="BA",$G15,0) | P15: =IF($D15="GF",$G15,0) | Q15: =IF($D15="OT",$G15,0) | R15: =IF($D15="AS",$G15,0) | T15: =IF($E15=T$8,$G15,0) | U15: =IF($E15=U$8,$G15,0) | V15: =IF($E15=V$8,$G15,0) | W15: =IF($E15=W$8,$G15,0) | X15: =IF($E15=X$8,$G15,0) | Y15: =IF($E15=Y$8,$G15,0) | Z15: =IF($E15=Z$8,$G15,0) | AA15: =IF($E15=AA$8,$G15,0) | ... DA15: =IF($E15=DA$8,$G15,0)
G16: =JUNIO!$I16-JUNIO!$H16 | N16: =IF($D16="AL",$G16,0) | O16: =IF($D16="BA",$G16,0) | P16: =IF($D16="GF",$G16,0) | Q16: =IF($D16="OT",$G16,0) | R16: =IF($D16="AS",$G16,0) | T16: =IF($E16=T$8,$G16,0) | U16: =IF($E16=U$8,$G16,0) | V16: =IF($E16=V$8,$G16,0) | W16: =IF($E16=W$8,$G16,0) | X16: =IF($E16=X$8,$G16,0) | Y16: =IF($E16=Y$8,$G16,0) | Z16: =IF($E16=Z$8,$G16,0) | AA16: =IF($E16=AA$8,$G16,0) | ... DA16: =IF($E16=DA$8,$G16,0)
G17: =JUNIO!$I17-JUNIO!$H17 | N17: =IF($D17="AL",$G17,0) | O17: =IF($D17="BA",$G17,0) | P17: =IF($D17="GF",$G17,0) | Q17: =IF($D17="OT",$G17,0) | R17: =IF($D17="AS",$G17,0) | T17: =IF($E17=T$8,$G17,0) | U17: =IF($E17=U$8,$G17,0) | V17: =IF($E17=V$8,$G17,0) | W17: =IF($E17=W$8,$G17,0) | X17: =IF($E17=X$8,$G17,0) | Y17: =IF($E17=Y$8,$G17,0) | Z17: =IF($E17=Z$8,$G17,0) | AA17: =IF($E17=AA$8,$G17,0) | ... DA17: =IF($E17=DA$8,$G17,0)
G18: =JUNIO!$I18-JUNIO!$H18 | N18: =IF($D18="AL",$G18,0) | O18: =IF($D18="BA",$G18,0) | P18: =IF($D18="GF",$G18,0) | Q18: =IF($D18="OT",$G18,0) | R18: =IF($D18="AS",$G18,0) | T18: =IF($E18=T$8,$G18,0) | U18: =IF($E18=U$8,$G18,0) | V18: =IF($E18=V$8,$G18,0) | W18: =IF($E18=W$8,$G18,0) | X18: =IF($E18=X$8,$G18,0) | Y18: =IF($E18=Y$8,$G18,0) | Z18: =IF($E18=Z$8,$G18,0) | AA18: =IF($E18=AA$8,$G18,0) | ... DA18: =IF($E18=DA$8,$G18,0)
G19: =JUNIO!$I19-JUNIO!$H19 | N19: =IF($D19="AL",$G19,0) | O19: =IF($D19="BA",$G19,0) | P19: =IF($D19="GF",$G19,0) | Q19: =IF($D19="OT",$G19,0) | R19: =IF($D19="AS",$G19,0) | T19: =IF($E19=T$8,$G19,0) | U19: =IF($E19=U$8,$G19,0) | V19: =IF($E19=V$8,$G19,0) | W19: =IF($E19=W$8,$G19,0) | X19: =IF($E19=X$8,$G19,0) | Y19: =IF($E19=Y$8,$G19,0) | Z19: =IF($E19=Z$8,$G19,0) | AA19: =IF($E19=AA$8,$G19,0) | ... DA19: =IF($E19=DA$8,$G19,0)
G20: =JUNIO!$I20-JUNIO!$H20 | N20: =IF($D20="AL",$G20,0) | O20: =IF($D20="BA",$G20,0) | P20: =IF($D20="GF",$G20,0) | Q20: =IF($D20="OT",$G20,0) | R20: =IF($D20="AS",$G20,0) | T20: =IF($E20=T$8,$G20,0) | U20: =IF($E20=U$8,$G20,0) | V20: =IF($E20=V$8,$G20,0) | W20: =IF($E20=W$8,$G20,0) | X20: =IF($E20=X$8,$G20,0) | Y20: =IF($E20=Y$8,$G20,0) | Z20: =IF($E20=Z$8,$G20,0) | AA20: =IF($E20=AA$8,$G20,0) | ... DA20: =IF($E20=DA$8,$G20,0)
... G246: =JUNIO!$I246-JUNIO!$H246 | N246: =IF($D246="AL",$G246,0) | O246: =IF($D246="BA",$G246,0) | P246: =IF($D246="GF",$G246,0) | Q246: =IF($D246="OT",$G246,0) | R246: =IF($D246="AS",$G246,0) | T246: =IF($E246=T$8,$G246,0) | U246: =IF($E246=U$8,$G246,0) | V246: =IF($E246=V$8,$G246,0) | W246: =IF($E246=W$8,$G246,0) | X246: =IF($E246=X$8,$G246,0) | Y246: =IF($E246=Y$8,$G246,0) | Z246: =IF($E246=Z$8,$G246,0) | AA246: =IF($E246=AA$8,$G246,0) | ... DA246: =IF($E246=DA$8,$G246,0)
G247: =JUNIO!$I247-JUNIO!$H247 | J247: - | N247: =IF($D247="AL",$G247,0) | O247: =IF($D247="BA",$G247,0) | P247: =IF($D247="GF",$G247,0) | Q247: =IF($D247="OT",$G247,0) | R247: =IF($D247="AS",$G247,0) | T247: =IF($E247=T$8,$G247,0) | U247: =IF($E247=U$8,$G247,0) | V247: =IF($E247=V$8,$G247,0) | W247: =IF($E247=W$8,$G247,0) | X247: =IF($E247=X$8,$G247,0) | Y247: =IF($E247=Y$8,$G247,0) | Z247: =IF($E247=Z$8,$G247,0) | AA247: =IF($E247=AA$8,$G247,0) | ... DA247: =IF($E247=DA$8,$G247,0)
G248: =JUNIO!$I248-JUNIO!$H248 | N248: =IF($D248="AL",$G248,0) | O248: =IF($D248="BA",$G248,0) | P248: =IF($D248="GF",$G248,0) | Q248: =IF($D248="OT",$G248,0) | R248: =IF($D248="AS",$G248,0) | T248: =IF($E248=T$8,$G248,0) | U248: =IF($E248=U$8,$G248,0) | V248: =IF($E248=V$8,$G248,0) | W248: =IF($E248=W$8,$G248,0) | X248: =IF($E248=X$8,$G248,0) | Y248: =IF($E248=Y$8,$G248,0) | Z248: =IF($E248=Z$8,$G248,0) | AA248: =IF($E248=AA$8,$G248,0) | ... DA248: =IF($E248=DA$8,$G248,0)
G249: =JUNIO!$I249-JUNIO!$H249 | N249: =IF($D249="AL",$G249,0) | O249: =IF($D249="BA",$G249,0) | P249: =IF($D249="GF",$G249,0) | Q249: =IF($D249="OT",$G249,0) | R249: =IF($D249="AS",$G249,0) | T249: =IF($E249=T$8,$G249,0) | U249: =IF($E249=U$8,$G249,0) | V249: =IF($E249=V$8,$G249,0) | W249: =IF($E249=W$8,$G249,0) | X249: =IF($E249=X$8,$G249,0) | Y249: =IF($E249=Y$8,$G249,0) | Z249: =IF($E249=Z$8,$G249,0) | AA249: =IF($E249=AA$8,$G249,0) | ... DA249: =IF($E249=DA$8,$G249,0)
G250: =JUNIO!$I250-JUNIO!$H250 | N250: =IF($D250="AL",$G250,0) | O250: =IF($D250="BA",$G250,0) | P250: =IF($D250="GF",$G250,0) | Q250: =IF($D250="OT",$G250,0) | R250: =IF($D250="AS",$G250,0) | T250: =IF($E250=T$8,$G250,0) | U250: =IF($E250=U$8,$G250,0) | V250: =IF($E250=V$8,$G250,0) | W250: =IF($E250=W$8,$G250,0) | X250: =IF($E250=X$8,$G250,0) | Y250: =IF($E250=Y$8,$G250,0) | Z250: =IF($E250=Z$8,$G250,0) | AA250: =IF($E250=AA$8,$G250,0) | ... DA250: =IF($E250=DA$8,$G250,0)
G251: =JUNIO!$I251-JUNIO!$H251 | N251: =IF($D251="AL",$G251,0) | O251: =IF($D251="BA",$G251,0) | P251: =IF($D251="GF",$G251,0) | Q251: =IF($D251="OT",$G251,0) | R251: =IF($D251="AS",$G251,0) | T251: =IF($E251=T$8,$G251,0) | U251: =IF($E251=U$8,$G251,0) | V251: =IF($E251=V$8,$G251,0) | W251: =IF($E251=W$8,$G251,0) | X251: =IF($E251=X$8,$G251,0) | Y251: =IF($E251=Y$8,$G251,0) | Z251: =IF($E251=Z$8,$G251,0) | AA251: =IF($E251=AA$8,$G251,0) | ... DA251: =IF($E251=DA$8,$G251,0)
G252: =JUNIO!$I252-JUNIO!$H252 | N252: =IF($D252="AL",$G252,0) | O252: =IF($D252="BA",$G252,0) | P252: =IF($D252="GF",$G252,0) | Q252: =IF($D252="OT",$G252,0) | R252: =IF($D252="AS",$G252,0) | T252: =IF($E252=T$8,$G252,0) | U252: =IF($E252=U$8,$G252,0) | V252: =IF($E252=V$8,$G252,0) | W252: =IF($E252=W$8,$G252,0) | X252: =IF($E252=X$8,$G252,0) | Y252: =IF($E252=Y$8,$G252,0) | Z252: =IF($E252=Z$8,$G252,0) | AA252: =IF($E252=AA$8,$G252,0) | ... DA252: =IF($E252=DA$8,$G252,0)
G253: =JUNIO!$I253-JUNIO!$H253 | N253: =IF($D253="AL",$G253,0) | O253: =IF($D253="BA",$G253,0) | P253: =IF($D253="GF",$G253,0) | Q253: =IF($D253="OT",$G253,0) | R253: =IF($D253="AS",$G253,0) | T253: =IF($E253=T$8,$G253,0) | U253: =IF($E253=U$8,$G253,0) | V253: =IF($E253=V$8,$G253,0) | W253: =IF($E253=W$8,$G253,0) | X253: =IF($E253=X$8,$G253,0) | Y253: =IF($E253=Y$8,$G253,0) | Z253: =IF($E253=Z$8,$G253,0) | AA253: =IF($E253=AA$8,$G253,0) | ... DA253: =IF($E253=DA$8,$G253,0)
G254: =JUNIO!$I254-JUNIO!$H254 | N254: =IF($D254="AL",$G254,0) | O254: =IF($D254="BA",$G254,0) | P254: =IF($D254="GF",$G254,0) | Q254: =IF($D254="OT",$G254,0) | R254: =IF($D254="AS",$G254,0) | T254: =IF($E254=T$8,$G254,0) | U254: =IF($E254=U$8,$G254,0) | V254: =IF($E254=V$8,$G254,0) | W254: =IF($E254=W$8,$G254,0) | X254: =IF($E254=X$8,$G254,0) | Y254: =IF($E254=Y$8,$G254,0) | Z254: =IF($E254=Z$8,$G254,0) | AA254: =IF($E254=AA$8,$G254,0) | ... DA254: =IF($E254=DA$8,$G254,0)
G255: =JUNIO!$I255-JUNIO!$H255 | N255: =IF($D255="AL",$G255,0) | O255: =IF($D255="BA",$G255,0) | P255: =IF($D255="GF",$G255,0) | Q255: =IF($D255="OT",$G255,0) | R255: =IF($D255="AS",$G255,0) | T255: =IF($E255=T$8,$G255,0) | U255: =IF($E255=U$8,$G255,0) | V255: =IF($E255=V$8,$G255,0) | W255: =IF($E255=W$8,$G255,0) | X255: =IF($E255=X$8,$G255,0) | Y255: =IF($E255=Y$8,$G255,0) | Z255: =IF($E255=Z$8,$G255,0) | AA255: =IF($E255=AA$8,$G255,0) | ... DA255: =IF($E255=DA$8,$G255,0)
G256: =JUNIO!$I256-JUNIO!$H256 | N256: =IF($D256="AL",$G256,0) | O256: =IF($D256="BA",$G256,0) | P256: =IF($D256="GF",$G256,0) | Q256: =IF($D256="OT",$G256,0) | R256: =IF($D256="AS",$G256,0) | T256: =IF($E256=T$8,$G256,0) | U256: =IF($E256=U$8,$G256,0) | V256: =IF($E256=V$8,$G256,0) | W256: =IF($E256=W$8,$G256,0) | X256: =IF($E256=X$8,$G256,0) | Y256: =IF($E256=Y$8,$G256,0) | Z256: =IF($E256=Z$8,$G256,0) | AA256: =IF($E256=AA$8,$G256,0) | ... DA256: =IF($E256=DA$8,$G256,0)
G257: =JUNIO!$I257-JUNIO!$H257 | N257: =IF($D257="AL",$G257,0) | O257: =IF($D257="BA",$G257,0) | P257: =IF($D257="GF",$G257,0) | Q257: =IF($D257="OT",$G257,0) | R257: =IF($D257="AS",$G257,0) | T257: =IF($E257=T$8,$G257,0) | U257: =IF($E257=U$8,$G257,0) | V257: =IF($E257=V$8,$G257,0) | W257: =IF($E257=W$8,$G257,0) | X257: =IF($E257=X$8,$G257,0) | Y257: =IF($E257=Y$8,$G257,0) | Z257: =IF($E257=Z$8,$G257,0) | AA257: =IF($E257=AA$8,$G257,0) | ... DA257: =IF($E257=DA$8,$G257,0)
G258: =JUNIO!$I258-JUNIO!$H258 | N258: =IF($D258="AL",$G258,0) | O258: =IF($D258="BA",$G258,0) | P258: =IF($D258="GF",$G258,0) | Q258: =IF($D258="OT",$G258,0) | R258: =IF($D258="AS",$G258,0) | T258: =IF($E258=T$8,$G258,0) | U258: =IF($E258=U$8,$G258,0) | V258: =IF($E258=V$8,$G258,0) | W258: =IF($E258=W$8,$G258,0) | X258: =IF($E258=X$8,$G258,0) | Y258: =IF($E258=Y$8,$G258,0) | Z258: =IF($E258=Z$8,$G258,0) | AA258: =IF($E258=AA$8,$G258,0) | ... DA258: =IF($E258=DA$8,$G258,0)
G259: =JUNIO!$I259-JUNIO!$H259 | N259: =IF($D259="AL",$G259,0) | O259: =IF($D259="BA",$G259,0) | P259: =IF($D259="GF",$G259,0) | Q259: =IF($D259="OT",$G259,0) | R259: =IF($D259="AS",$G259,0) | T259: =IF($E259=T$8,$G259,0) | U259: =IF($E259=U$8,$G259,0) | V259: =IF($E259=V$8,$G259,0) | W259: =IF($E259=W$8,$G259,0) | X259: =IF($E259=X$8,$G259,0) | Y259: =IF($E259=Y$8,$G259,0) | Z259: =IF($E259=Z$8,$G259,0) | AA259: =IF($E259=AA$8,$G259,0) | ... DA259: =IF($E259=DA$8,$G259,0)
... G286: =JUNIO!$I286-JUNIO!$H286 | N286: =IF($D286="AL",$G286,0) | O286: =IF($D286="BA",$G286,0) | P286: =IF($D286="GF",$G286,0) | Q286: =IF($D286="OT",$G286,0) | R286: =IF($D286="AS",$G286,0) | T286: =IF($E286=T$8,$G286,0) | U286: =IF($E286=U$8,$G286,0) | V286: =IF($E286=V$8,$G286,0) | W286: =IF($E286=W$8,$G286,0) | X286: =IF($E286=X$8,$G286,0) | Y286: =IF($E286=Y$8,$G286,0) | Z286: =IF($E286=Z$8,$G286,0) | AA286: =IF($E286=AA$8,$G286,0) | ... DA286: =IF($E286=DA$8,$G286,0)
G287: 22222 | N287: =IF($D287="AL",$G287,0) | O287: =IF($D287="BA",$G287,0) | P287: =IF($D287="GF",$G287,0) | Q287: =IF($D287="OT",$G287,0) | R287: =IF($D287="AS",$G287,0) | T287: =IF($E287=T$8,$G287,0) | U287: =IF($E287=U$8,$G287,0) | V287: =IF($E287=V$8,$G287,0) | W287: =IF($E287=W$8,$G287,0) | X287: =IF($E287=X$8,$G287,0) | Y287: =IF($E287=Y$8,$G287,0) | Z287: =IF($E287=Z$8,$G287,0) | AA287: =IF($E287=AA$8,$G287,0) | ... DA287: =IF($E287=DA$8,$G287,0)
G288: =JUNIO!$I288-JUNIO!$H288 | N288: =IF($D288="AL",$G288,0) | O288: =IF($D288="BA",$G288,0) | P288: =IF($D288="GF",$G288,0) | Q288: =IF($D288="OT",$G288,0) | R288: =IF($D288="AS",$G288,0) | T288: =IF($E288=T$8,$G288,0) | U288: =IF($E288=U$8,$G288,0) | V288: =IF($E288=V$8,$G288,0) | W288: =IF($E288=W$8,$G288,0) | X288: =IF($E288=X$8,$G288,0) | Y288: =IF($E288=Y$8,$G288,0) | Z288: =IF($E288=Z$8,$G288,0) | AA288: =IF($E288=AA$8,$G288,0) | ... DA288: =IF($E288=DA$8,$G288,0)
G289: =JUNIO!$I289-JUNIO!$H289 | N289: =IF($D289="AL",$G289,0) | O289: =IF($D289="BA",$G289,0) | P289: =IF($D289="GF",$G289,0) | Q289: =IF($D289="OT",$G289,0) | R289: =IF($D289="AS",$G289,0) | T289: =IF($E289=T$8,$G289,0) | U289: =IF($E289=U$8,$G289,0) | V289: =IF($E289=V$8,$G289,0) | W289: =IF($E289=W$8,$G289,0) | X289: =IF($E289=X$8,$G289,0) | Y289: =IF($E289=Y$8,$G289,0) | Z289: =IF($E289=Z$8,$G289,0) | AA289: =IF($E289=AA$8,$G289,0) | ... DA289: =IF($E289=DA$8,$G289,0)
G290: =JUNIO!$I290-JUNIO!$H290 | N290: =IF($D290="AL",$G290,0) | O290: =IF($D290="BA",$G290,0) | P290: =IF($D290="GF",$G290,0) | Q290: =IF($D290="OT",$G290,0) | R290: =IF($D290="AS",$G290,0) | T290: =IF($E290=T$8,$G290,0) | U290: =IF($E290=U$8,$G290,0) | V290: =IF($E290=V$8,$G290,0) | W290: =IF($E290=W$8,$G290,0) | X290: =IF($E290=X$8,$G290,0) | Y290: =IF($E290=Y$8,$G290,0) | Z290: =IF($E290=Z$8,$G290,0) | AA290: =IF($E290=AA$8,$G290,0) | ... DA290: =IF($E290=DA$8,$G290,0)
G291: =JUNIO!$I291-JUNIO!$H291 | N291: =IF($D291="AL",$G291,0) | O291: =IF($D291="BA",$G291,0) | P291: =IF($D291="GF",$G291,0) | Q291: =IF($D291="OT",$G291,0) | R291: =IF($D291="AS",$G291,0) | T291: =IF($E291=T$8,$G291,0) | U291: =IF($E291=U$8,$G291,0) | V291: =IF($E291=V$8,$G291,0) | W291: =IF($E291=W$8,$G291,0) | X291: =IF($E291=X$8,$G291,0) | Y291: =IF($E291=Y$8,$G291,0) | Z291: =IF($E291=Z$8,$G291,0) | AA291: =IF($E291=AA$8,$G291,0) | ... DA291: =IF($E291=DA$8,$G291,0)
G292: =JUNIO!$I292-JUNIO!$H292 | N292: =IF($D292="AL",$G292,0) | O292: =IF($D292="BA",$G292,0) | P292: =IF($D292="GF",$G292,0) | Q292: =IF($D292="OT",$G292,0) | R292: =IF($D292="AS",$G292,0) | T292: =IF($E292=T$8,$G292,0) | U292: =IF($E292=U$8,$G292,0) | V292: =IF($E292=V$8,$G292,0) | W292: =IF($E292=W$8,$G292,0) | X292: =IF($E292=X$8,$G292,0) | Y292: =IF($E292=Y$8,$G292,0) | Z292: =IF($E292=Z$8,$G292,0) | AA292: =IF($E292=AA$8,$G292,0) | ... DA292: =IF($E292=DA$8,$G292,0)
G293: =JUNIO!$I293-JUNIO!$H293 | N293: =IF($D293="AL",$G293,0) | O293: =IF($D293="BA",$G293,0) | P293: =IF($D293="GF",$G293,0) | Q293: =IF($D293="OT",$G293,0) | R293: =IF($D293="AS",$G293,0) | T293: =IF($E293=T$8,$G293,0) | U293: =IF($E293=U$8,$G293,0) | V293: =IF($E293=V$8,$G293,0) | W293: =IF($E293=W$8,$G293,0) | X293: =IF($E293=X$8,$G293,0) | Y293: =IF($E293=Y$8,$G293,0) | Z293: =IF($E293=Z$8,$G293,0) | AA293: =IF($E293=AA$8,$G293,0) | ... DA293: =IF($E293=DA$8,$G293,0)
...
