Workbook

Sheet S1 Lunes
D2: PRODUCTOS | E2: + | F2: + | G2: (-) | H2: (-) | I2: = | J2: = | K2: = | L2: $ | N2: $
E3: Stock Inicial | F3: Entregas | G3: Ventas | H3: Mermas | I3: Stock Real | J3: Stock Informado | K3: Diferencias | L3: Precio | N3: Descuento
D4: Atún Steak | F4: =E221 | G4: =IFERROR(SUMPRODUCT(($F$66:$F$153="Atún Steak")*$E$66:$E$153*$G$66:$G$153),"Error") | H4: =SUM(F159:J159) | I4: =E4+F4-G4-H4 | J4: =E159 | K4: =J4-I4 | L4: =+'MERMAS S1'!D5 | N4: =IF(K4<0,K4*L4,0)
D5: Atún Trozos | F5: =E222 | G5: =IFERROR(SUMPRODUCT(($F$66:$F$153="Atún Trozos")*$E$66:$E$153*$G$66:$G$153),"Error") | H5: =SUM(F160:I160)+SUM(F190:I190) | I5: =E5+F5-G5-H5 | J5: =E160+E190 | K5: =J5-I5 | L5: =+'MERMAS S1'!D6 | N5: =IF(K5<0,K5*L5,0)
D6: Almejas Julianas | F6: =E254 | G6: =K254 | H6: =SUM(F161:I161)+J254 | I6: =E6+F6-G6-H6 | J6: =E161 | K6: =J6-I6 | L6: =+'MERMAS S1'!D7 | N6: =IF(K6<0,K6*L6,0)
D7: Carpaccio de res | F7: =E223 | G7: =IFERROR(SUMPRODUCT(($F$66:$F$153="Carpaccio de res")*$E$66:$E$153*$G$66:$G$153),"Error") | H7: =SUM(F162:I162) | I7: =E7+F7-G7-H7 | J7: =E162 | K7: =J7-I7 | L7: =+'MERMAS S1'!D8 | N7: =IF(K7<0,K7*L7,0)
D8: Chupe | F8: =H258 | G8: =E90 | H8: =SUM(F165:I165) | I8: =E8+F8-G8-H8 | J8: =E165 | K8: =J8-I8 | L8: =+'MERMAS S1'!D9 | N8: =IF(K8<0,K8*L8,0)
D9: Congrio | F9: =E252 | G9: =IFERROR(SUMPRODUCT(($F$66:$F$153="Congrio")*$E$66:$E$153*$G$66:$G$153),"Error") | H9: =J252+SUM(F164:I164) | I9: =E9+F9-G9-H9 | J9: =E164 | K9: =J9-I9 | L9: =+'MERMAS S1'!D10 | N9: =IF(K9<0,K9*L9,0)
D10: Filete despunte | F10: =E255 | G10: =K255+K256 | H10: =SUM(J255:J256)+SUM(F167:I167) | I10: =E10+F10-G10-H10 | J10: =E167 | K10: =J10-I10 | L10: =+'MERMAS S1'!D11 | N10: =IF(K10<0,K10*L10,0)
D11: Filete para churrasco | F11: =E226 | G11: =IFERROR(SUMPRODUCT(($F$66:$F$153="Filete para churrasco")*$E$66:$E$153*$G$66:$G$153),"Error") | H11: =SUM(F168:I168) | I11: =E11+F11-G11-H11 | J11: =E168 | K11: =J11-I11 | L11: =+'MERMAS S1'!D12 | N11: =IF(K11<0,K11*L11,0)
D12: Filete para crudo | F12: =E227 | G12: =IFERROR(SUMPRODUCT(($F$66:$F$153="Filete para crudo")*$E$66:$E$153*$G$66:$G$153),"Error") | H12: =SUM(F169:I169)+SUM(F189:I189) | I12: =E12+F12-G12-H12 | J12: =E169 +IFERROR(INDEX($E$159:$E$215,MATCH("Tartar de Res",$D$159:$D$215,0)),0) | K12: =J12-I12 | L12: =+'MERMAS S1'!D13 | N12: =IF(K12<0,K12*L12,0)
D13: Filete Salteado | F13: =E228 | G13: =IFERROR(SUMPRODUCT(($F$66:$F$153=D13)*$E$66:$E$153*$G$66:$G$153),"Error") | H13: =SUM(F170:I170) | I13: =E13+F13-G13-H13 | J13: =E170 | K13: =J13-I13 | L13: =+'MERMAS S1'!D14 | N13: =IF(K13<0,K13*L13,0)
D14: Ganso | F14: =E229 | G14: =IFERROR(SUMPRODUCT(($F$66:$F$153=D14)*$E$66:$E$153*$G$66:$G$153),"Error") | H14: =SUM(F171:I171)+SUM(F180:I180) | I14: =E14+F14-G14-H14 | J14: =E171 +IFERROR(INDEX($E$159:$E$215,MATCH("Paila de Carne",$D$159:$D$215,0)),0) | K14: =J14-I14 | L14: =+'MERMAS S1'!D15 | N14: =IF(K14<0,K14*L14,0)
D15: Hamburguesas | F15: =E231 | G15: =IFERROR(SUMPRODUCT(($F$66:$F$153=D15)*$E$66:$E$153*$G$66:$G$153),"Error") | H15: =SUM(F172:I172) | I15: =E15+F15-G15-H15 | J15: =E172 | K15: =J15-I15 | L15: =+'MERMAS S1'!D16 | N15: =IF(K15<0,K15*L15,0)
D16: Jamón serrano | F16: =E232 | G16: =IFERROR(SUMPRODUCT(($F$66:$F$153=D16)*$E$66:$E$153*$G$66:$G$153),"Error") | H16: =SUM(F174:I174) | I16: =E16+F16-G16-H16 | J16: =E174 | K16: =J16-I16 | L16: =+'MERMAS S1'!D17 | N16: =IF(K16<0,K16*L16,0)
D17: Langostinos | F17: =H248 | G17: =IFERROR(SUMPRODUCT(($F$66:$F$153=D17)*$E$66:$E$153*$G$66:$G$153),"Error") | H17: =SUM(F173:I173) | I17: =E17+F17-G17-H17 | J17: =E173 | K17: =J17-I17 | L17: =+'MERMAS S1'!D18 | N17: =IF(K17<0,K17*L17,0)
D18: Lasagna de Berenjenas | F18: =H257 | G18: =E120 | H18: =SUM(F175:I175) | I18: =E18+F18-G18-H18 | J18: =E175 | K18: =J18-I18 | L18: =+'MERMAS S1'!D19 | N18: =IF(K18<0,K18*L18,0)
D19: Locos | F19: =E249 | G19: =IFERROR(SUMPRODUCT(($F$66:$F$153=D19)*$E$66:$E$153*$G$66:$G$153),"Error") | H19: =SUM(F177:I177)+J249 | I19: =E19+F19-G19-H19 | J19: =E177 | K19: =J19-I19 | L19: =+'MERMAS S1'!D20 | N19: =IF(K19<0,K19*L19,0)
D20: Lomo liso | F20: =E233 | G20: =IFERROR(SUMPRODUCT(($F$66:$F$153=D20)*$E$66:$E$153*$G$66:$G$153),"Error") | H20: =SUM(F176:I176) | I20: =E20+F20-G20-H20 | J20: =E176 | K20: =J20-I20 | L20: =+'MERMAS S1'!D21 | N20: =IF(K20<0,K20*L20,0)
D21: Mejillones | F21: =E253 | G21: =K253 | H21: =J253+SUM(F178:I178) | I21: =E21+F21-G21-H21 | J21: =E178 | K21: =J21-I21 | L21: =+'MERMAS S1'!D22 | N21: =IF(K21<0,K21*L21,0)
D22: Merluza | F22: =E250 | G22: =IFERROR(SUMPRODUCT(($F$66:$F$153=D22)*$E$66:$E$153*$G$66:$G$153),"Error") | H22: =SUM(F179:I179)+J250 | I22: =E22+F22-G22-H22 | J22: =E179 | K22: =J22-I22 | L22: =+'MERMAS S1'!D23 | N22: =IF(K22<0,K22*L22,0)
D23: Plateada | F23: =E234 | G23: =IFERROR(SUMPRODUCT(($F$66:$F$153=D23)*$E$66:$E$153*$G$66:$G$153),"Error") | H23: =SUM(F181:I181) | I23: =E23+F23-G23-H23 | J23: =E181 | K23: =J23-I23 | L23: =+'MERMAS S1'!D24 | N23: =IF(K23<0,K23*L23,0)
D24: Pulpo | F24: =E235 | G24: =IFERROR(SUMPRODUCT(($F$66:$F$153=D24)*$E$66:$E$153*$G$66:$G$153),"Error") | H24: =SUM(F182:I182) | I24: =E24+F24-G24-H24 | J24: =E182 | K24: =J24-I24 | L24: =+'MERMAS S1'!D25 | N24: =IF(K24<0,K24*L24,0)
D25: Ragout Lasagna | F25: =H255 | G25: =E257 | H25: =SUM(F183:I183)+J257 | I25: =E25+F25-G25-H25 | J25: =E183 | K25: =J25-I25 | L25: =+'MERMAS S1'!D26 | N25: =IF(K25<0,K25*L25,0)
D26: Ragout Rigatoni | F26: =H256 | G26: =E133 | H26: =SUM(F184:I184) | I26: =E26+F26-G26-H26 | J26: =E184 | K26: =J26-I26 | L26: =+'MERMAS S1'!D27 | N26: =IF(K26<0,K26*L26,0)
D27: Reineta | F27: =E251 | G27: =IFERROR(SUMPRODUCT(($F$66:$F$153=D27)*$E$66:$E$153*$G$66:$G$153),"Error") | H27: =SUM(F163:I163)+J251 | I27: =E27+F27-G27-H27 | J27: =E163 | K27: =J27-I27 | L27: =+'MERMAS S1'!D28 | N27: =IF(K27<0,K27*L27,0)
D28: Salmón ahumado en frío | F28: =E258 | G28: =K258 | H28: =J258 | I28: =E28+F28-G28-H28 | J28: =E185 | K28: =J28-I28 | L28: =+'MERMAS S1'!D29 | N28: =IF(K28<0,K28*L28,0)
D29: Salmón ahumado en Caliente | F29: =E237 | G29: =IFERROR(SUMPRODUCT(($F$66:$F$153=D29)*$E$66:$E$153*$G$66:$G$153),"Error") | H29: =SUM(F186:I186) | I29: =E29+F29-G29-H29 | J29: =E186 | K29: =J29-I29 | L29: =+'MERMAS S1'!D30 | N29: =IF(K29<0,K29*L29,0)
D30: Salmón cancato | F30: =E238 | G30: =IFERROR(SUMPRODUCT(($F$66:$F$153=D30)*$E$66:$E$153*$G$66:$G$153),"Error") | H30: =SUM(F187:I187) | I30: =E30+F30-G30-H30 | J30: =E187 | K30: =J30-I30 | L30: =+'MERMAS S1'!D31 | N30: =IF(K30<0,K30*L30,0)
D31: Salmón fresco premium | F31: =E239 | G31: =IFERROR(SUMPRODUCT(($F$66:$F$153=D31)*$E$66:$E$153*$G$66:$G$153),"Error") | H31: =SUM(F188:I188) | I31: =E31+F31-G31-H31 | J31: =E188 | K31: =J31-I31 | L31: =+'MERMAS S1'!D32 | N31: =IF(K31<0,K31*L31,0)
I33: DIFERENCIAS PROMEDIO | K33: =SUM(K7:K31) | M33: DCTO. TOTAL | N33: =SUM(N7:N31)
F35: + | G35: (-) | H35: (-) | I35: = | J35: = | K35: = | L35: $ | N35: $
D36: PRODUCTOS | F36: Entregas | G36: Ventas | H36: Mermas | I36: Stock Real | J36: Stock Informado | K36: Diferencias | L36: Precio | N36: Descuento
D37: Brownie Nutella | F37: =E264 | G37: =IFERROR(SUMPRODUCT(($F$66:$F$153=D37)*$E$66:$E$153*$G$66:$G$153),"Error") | H37: =SUM(F194:I194) | I37: =E37+F37-G37-H37 | J37: =E194 | K37: =J37-I37 | L37: =+'MERMAS S1'!D33 | N37: =IF(K37<0,K37*L37,0)
D38: Brownie Vegano | F38: =E265 | G38: =IFERROR(SUMPRODUCT(($F$66:$F$153=D38)*$E$66:$E$153*$G$66:$G$153),"Error") | H38: =SUM(F195:I195) | I38: =E38+F38-G38-H38 | J38: =E195 | K38: =J38-I38 | L38: =+'MERMAS S1'!D34 | N38: =IF(K38<0,K38*L38,0)
D39: Cheesecake de Berries | F39: =E262 | G39: =IFERROR(SUMPRODUCT(($F$66:$F$153="Cheesecake Berries")*$E$66:$E$153*$G$66:$G$153),"Error") | H39: =SUM(F196:I196) | I39: =E39+F39-G39-H39 | J39: =E196 | K39: =J39-I39 | L39: =+'MERMAS S1'!D35 | N39: =IF(K39<0,K39*L39,0)
D40: Cheesecake de Limón | F40: =E263 | G40: =IFERROR(SUMPRODUCT(($F$66:$F$153=D40)*$E$66:$E$153*$G$66:$G$153),"Error") | H40: =SUM(F197:H197) | I40: =E40+F40-G40-H40 | J40: =E197 | K40: =J40-I40 | L40: =+'MERMAS S1'!D36 | N40: =IF(K40<0,K40*L40,0)
D41: Chocolate Blanco | F41: =H262 | G41: =J262 | H41: =SUM(F198:I198) | I41: =E41+F41-G41-H41 | J41: =E198 | K41: =J41-I41 | L41: =+'MERMAS S1'!D37 | N41: =IF(K41<0,K41*L41,0)
D42: Chocolate Leche | F42: =H263 | G42: =J263 | H42: =SUM(F199:I199) | I42: =E42+F42-G42-H42 | J42: =E199 | K42: =J42-I42 | L42: =+'MERMAS S1'!D38 | N42: =IF(K42<0,K42*L42,0)
D43: Chocolate Negro | F43: =H264 | G43: =J264 | H43: =SUM(F200:I200) | I43: =E43+F43-G43-H43 | J43: =E200 | K43: =J43-I43 | L43: =+'MERMAS S1'!D39 | N43: =IF(K43<0,K43*L43,0)
...

Sheet S1 Martes
D2: PRODUCTOS | E2: + | F2: + | G2: (-) | H2: (-) | I2: = | J2: = | K2: = | L2: $ | N2: $
E3: Stock Inicial | F3: Entregas | G3: Ventas | H3: Mermas | I3: Stock Real | J3: Stock Informado | K3: Diferencias | L3: Precio | N3: Descuento
D4: Atún Steak | F4: =E221 | G4: =IFERROR(SUMPRODUCT(($F$66:$F$153="Atún Steak")*$E$66:$E$153*$G$66:$G$153),"Error") | H4: =SUM(F159:J159) | I4: =E4+F4-G4-H4 | J4: =E159 | K4: =J4-I4 | L4: =+'MERMAS S1'!D5 | N4: =IF(K4<0,K4*L4,0)
D5: Atún Trozos | F5: =E222 | G5: =IFERROR(SUMPRODUCT(($F$66:$F$153="Atún Trozos")*$E$66:$E$153*$G$66:$G$153),"Error") | H5: =SUM(F160:I160)+SUM(F190:I190) | I5: =E5+F5-G5-H5 | J5: =E160+E190 | K5: =J5-I5 | L5: =+'MERMAS S1'!D6 | N5: =IF(K5<0,K5*L5,0)
D6: Almejas Julianas | F6: =E254 | G6: =K254 | H6: =SUM(F161:I161)+J254 | I6: =E6+F6-G6-H6 | J6: =E161 | K6: =J6-I6 | L6: =+'MERMAS S1'!D7 | N6: =IF(K6<0,K6*L6,0)
D7: Carpaccio de res | F7: =E223 | G7: =IFERROR(SUMPRODUCT(($F$66:$F$153="Carpaccio de res")*$E$66:$E$153*$G$66:$G$153),"Error") | H7: =SUM(F162:I162) | I7: =E7+F7-G7-H7 | J7: =E162 | K7: =J7-I7 | L7: =+'MERMAS S1'!D8 | N7: =IF(K7<0,K7*L7,0)
D8: Chupe | F8: =H258 | G8: =E90 | H8: =SUM(F165:I165) | I8: =E8+F8-G8-H8 | J8: =E165 | K8: =J8-I8 | L8: =+'MERMAS S1'!D9 | N8: =IF(K8<0,K8*L8,0)
D9: Congrio | F9: =E252 | G9: =IFERROR(SUMPRODUCT(($F$66:$F$153="Congrio")*$E$66:$E$153*$G$66:$G$153),"Error") | H9: =J252+SUM(F164:I164) | I9: =E9+F9-G9-H9 | J9: =E164 | K9: =J9-I9 | L9: =+'MERMAS S1'!D10 | N9: =IF(K9<0,K9*L9,0)
D10: Filete despunte | F10: =E255 | G10: =K255+K256 | H10: =SUM(J255:J256)+SUM(F167:I167) | I10: =E10+F10-G10-H10 | J10: =E167 | K10: =J10-I10 | L10: =+'MERMAS S1'!D11 | N10: =IF(K10<0,K10*L10,0)
D11: Filete para churrasco | F11: =E226 | G11: =IFERROR(SUMPRODUCT(($F$66:$F$153="Filete para churrasco")*$E$66:$E$153*$G$66:$G$153),"Error") | H11: =SUM(F168:I168) | I11: =E11+F11-G11-H11 | J11: =E168 | K11: =J11-I11 | L11: =+'MERMAS S1'!D12 | N11: =IF(K11<0,K11*L11,0)
D12: Filete para crudo | F12: =E227 | G12: =IFERROR(SUMPRODUCT(($F$66:$F$153="Filete para crudo")*$E$66:$E$153*$G$66:$G$153),"Error") | H12: =SUM(F169:I169)+SUM(F189:I189) | I12: =E12+F12-G12-H12 | J12: =E169 +IFERROR(INDEX($E$159:$E$215,MATCH("Tartar de Res",$D$159:$D$215,0)),0) | K12: =J12-I12 | L12: =+'MERMAS S1'!D13 | N12: =IF(K12<0,K12*L12,0)
D13: Filete Salteado | F13: =E228 | G13: =IFERROR(SUMPRODUCT(($F$66:$F$153=D13)*$E$66:$E$153*$G$66:$G$153),"Error") | H13: =SUM(F170:I170) | I13: =E13+F13-G13-H13 | J13: =E170 | K13: =J13-I13 | L13: =+'MERMAS S1'!D14 | N13: =IF(K13<0,K13*L13,0)
D14: Ganso | F14: =E229 | G14: =IFERROR(SUMPRODUCT(($F$66:$F$153=D14)*$E$66:$E$153*$G$66:$G$153),"Error") | H14: =SUM(F171:I171)+SUM(F180:I180) | I14: =E14+F14-G14-H14 | J14: =E171 +IFERROR(INDEX($E$159:$E$215,MATCH("Paila de Carne",$D$159:$D$215,0)),0) | K14: =J14-I14 | L14: =+'MERMAS S1'!D15 | N14: =IF(K14<0,K14*L14,0)
D15: Hamburguesas | F15: =E231 | G15: =IFERROR(SUMPRODUCT(($F$66:$F$153=D15)*$E$66:$E$153*$G$66:$G$153),"Error") | H15: =SUM(F172:I172) | I15: =E15+F15-G15-H15 | J15: =E172 | K15: =J15-I15 | L15: =+'MERMAS S1'!D16 | N15: =IF(K15<0,K15*L15,0)
D16: Jamón serrano | F16: =E232 | G16: =IFERROR(SUMPRODUCT(($F$66:$F$153=D16)*$E$66:$E$153*$G$66:$G$153),"Error") | H16: =SUM(F174:I174) | I16: =E16+F16-G16-H16 | J16: =E174 | K16: =J16-I16 | L16: =+'MERMAS S1'!D17 | N16: =IF(K16<0,K16*L16,0)
D17: Langostinos | F17: =H248 | G17: =IFERROR(SUMPRODUCT(($F$66:$F$153=D17)*$E$66:$E$153*$G$66:$G$153),"Error") | H17: =SUM(F173:I173) | I17: =E17+F17-G17-H17 | J17: =E173 | K17: =J17-I17 | L17: =+'MERMAS S1'!D18 | N17: =IF(K17<0,K17*L17,0)
D18: Lasagna de Berenjenas | F18: =H257 | G18: =E120 | H18: =SUM(F175:I175) | I18: =E18+F18-G18-H18 | J18: =E175 | K18: =J18-I18 | L18: =+'MERMAS S1'!D19 | N18: =IF(K18<0,K18*L18,0)
D19: Locos | F19: =E249 | G19: =IFERROR(SUMPRODUCT(($F$66:$F$153=D19)*$E$66:$E$153*$G$66:$G$153),"Error") | H19: =SUM(F177:I177)+J249 | I19: =E19+F19-G19-H19 | J19: =E177 | K19: =J19-I19 | L19: =+'MERMAS S1'!D20 | N19: =IF(K19<0,K19*L19,0)
D20: Lomo liso | F20: =E233 | G20: =IFERROR(SUMPRODUCT(($F$66:$F$153=D20)*$E$66:$E$153*$G$66:$G$153),"Error") | H20: =SUM(F176:I176) | I20: =E20+F20-G20-H20 | J20: =E176 | K20: =J20-I20 | L20: =+'MERMAS S1'!D21 | N20: =IF(K20<0,K20*L20,0)
D21: Mejillones | F21: =E253 | G21: =K253 | H21: =J253+SUM(F178:I178) | I21: =E21+F21-G21-H21 | J21: =E178 | K21: =J21-I21 | L21: =+'MERMAS S1'!D22 | N21: =IF(K21<0,K21*L21,0)
D22: Merluza | F22: =E250 | G22: =IFERROR(SUMPRODUCT(($F$66:$F$153=D22)*$E$66:$E$153*$G$66:$G$153),"Error") | H22: =SUM(F179:I179)+J250 | I22: =E22+F22-G22-H22 | J22: =E179 | K22: =J22-I22 | L22: =+'MERMAS S1'!D23 | N22: =IF(K22<0,K22*L22,0)
D23: Plateada | F23: =E234 | G23: =IFERROR(SUMPRODUCT(($F$66:$F$153=D23)*$E$66:$E$153*$G$66:$G$153),"Error") | H23: =SUM(F181:I181) | I23: =E23+F23-G23-H23 | J23: =E181 | K23: =J23-I23 | L23: =+'MERMAS S1'!D24 | N23: =IF(K23<0,K23*L23,0)
D24: Pulpo | F24: =E235 | G24: =IFERROR(SUMPRODUCT(($F$66:$F$153=D24)*$E$66:$E$153*$G$66:$G$153),"Error") | H24: =SUM(F182:I182) | I24: =E24+F24-G24-H24 | J24: =E182 | K24: =J24-I24 | L24: =+'MERMAS S1'!D25 | N24: =IF(K24<0,K24*L24,0)
D25: Ragout Lasagna | F25: =H255 | G25: =E257 | H25: =SUM(F183:I183)+J257 | I25: =E25+F25-G25-H25 | J25: =E183 | K25: =J25-I25 | L25: =+'MERMAS S1'!D26 | N25: =IF(K25<0,K25*L25,0)
D26: Ragout Rigatoni | F26: =H256 | G26: =E133 | H26: =SUM(F184:I184) | I26: =E26+F26-G26-H26 | J26: =E184 | K26: =J26-I26 | L26: =+'MERMAS S1'!D27 | N26: =IF(K26<0,K26*L26,0)
D27: Reineta | F27: =E251 | G27: =IFERROR(SUMPRODUCT(($F$66:$F$153=D27)*$E$66:$E$153*$G$66:$G$153),"Error") | H27: =SUM(F163:I163)+J251 | I27: =E27+F27-G27-H27 | J27: =E163 | K27: =J27-I27 | L27: =+'MERMAS S1'!D28 | N27: =IF(K27<0,K27*L27,0)
D28: Salmón ahumado en frío | F28: =E258 | G28: =K258 | H28: =J258 | I28: =E28+F28-G28-H28 | J28: =E185 | K28: =J28-I28 | L28: =+'MERMAS S1'!D29 | N28: =IF(K28<0,K28*L28,0)
D29: Salmón ahumado en Caliente | F29: =E237 | G29: =IFERROR(SUMPRODUCT(($F$66:$F$153=D29)*$E$66:$E$153*$G$66:$G$153),"Error") | H29: =SUM(F186:I186) | I29: =E29+F29-G29-H29 | J29: =E186 | K29: =J29-I29 | L29: =+'MERMAS S1'!D30 | N29: =IF(K29<0,K29*L29,0)
D30: Salmón cancato | F30: =E238 | G30: =IFERROR(SUMPRODUCT(($F$66:$F$153=D30)*$E$66:$E$153*$G$66:$G$153),"Error") | H30: =SUM(F187:I187) | I30: =E30+F30-G30-H30 | J30: =E187 | K30: =J30-I30 | L30: =+'MERMAS S1'!D31 | N30: =IF(K30<0,K30*L30,0)
D31: Salmón fresco premium | F31: =E239 | G31: =IFERROR(SUMPRODUCT(($F$66:$F$153=D31)*$E$66:$E$153*$G$66:$G$153),"Error") | H31: =SUM(F188:I188) | I31: =E31+F31-G31-H31 | J31: =E188 | K31: =J31-I31 | L31: =+'MERMAS S1'!D32 | N31: =IF(K31<0,K31*L31,0)
I33: DIFERENCIAS PROMEDIO | K33: =SUM(K7:K31) | M33: DCTO. TOTAL | N33: =SUM(N7:N31)
F35: + | G35: (-) | H35: (-) | I35: = | J35: = | K35: = | L35: $ | N35: $
D36: PRODUCTOS | F36: Entregas | G36: Ventas | H36: Mermas | I36: Stock Real | J36: Stock Informado | K36: Diferencias | L36: Precio | N36: Descuento
D37: Brownie Nutella | F37: =E264 | G37: =IFERROR(SUMPRODUCT(($F$66:$F$153=D37)*$E$66:$E$153*$G$66:$G$153),"Error") | H37: =SUM(F194:I194) | I37: =E37+F37-G37-H37 | J37: =E194 | K37: =J37-I37 | L37: =+'MERMAS S1'!D33 | N37: =IF(K37<0,K37*L37,0)
D38: Brownie Vegano | F38: =E265 | G38: =IFERROR(SUMPRODUCT(($F$66:$F$153=D38)*$E$66:$E$153*$G$66:$G$153),"Error") | H38: =SUM(F195:I195) | I38: =E38+F38-G38-H38 | J38: =E195 | K38: =J38-I38 | L38: =+'MERMAS S1'!D34 | N38: =IF(K38<0,K38*L38,0)
D39: Cheesecake de Berries | F39: =E262 | G39: =IFERROR(SUMPRODUCT(($F$66:$F$153="Cheesecake Berries")*$E$66:$E$153*$G$66:$G$153),"Error") | H39: =SUM(F196:I196) | I39: =E39+F39-G39-H39 | J39: =E196 | K39: =J39-I39 | L39: =+'MERMAS S1'!D35 | N39: =IF(K39<0,K39*L39,0)
D40: Cheesecake de Limón | F40: =E263 | G40: =IFERROR(SUMPRODUCT(($F$66:$F$153=D40)*$E$66:$E$153*$G$66:$G$153),"Error") | H40: =SUM(F197:H197) | I40: =E40+F40-G40-H40 | J40: =E197 | K40: =J40-I40 | L40: =+'MERMAS S1'!D36 | N40: =IF(K40<0,K40*L40,0)
D41: Chocolate Blanco | F41: =H262 | G41: =J262 | H41: =SUM(F198:I198) | I41: =E41+F41-G41-H41 | J41: =E198 | K41: =J41-I41 | L41: =+'MERMAS S1'!D37 | N41: =IF(K41<0,K41*L41,0)
D42: Chocolate Leche | F42: =H263 | G42: =J263 | H42: =SUM(F199:I199) | I42: =E42+F42-G42-H42 | J42: =E199 | K42: =J42-I42 | L42: =+'MERMAS S1'!D38 | N42: =IF(K42<0,K42*L42,0)
D43: Chocolate Negro | F43: =H264 | G43: =J264 | H43: =SUM(F200:I200) | I43: =E43+F43-G43-H43 | J43: =E200 | K43: =J43-I43 | L43: =+'MERMAS S1'!D39 | N43: =IF(K43<0,K43*L43,0)
...

Sheet S1 Miércoles
D2: PRODUCTOS | E2: + | F2: + | G2: (-) | H2: (-) | I2: = | J2: = | K2: = | L2: $ | N2: $
E3: Stock Inicial | F3: Entregas | G3: Ventas | H3: Mermas | I3: Stock Real | J3: Stock Informado | K3: Diferencias | L3: Precio | N3: Descuento
D4: Atún Steak | F4: =E221 | G4: =IFERROR(SUMPRODUCT(($F$66:$F$153="Atún Steak")*$E$66:$E$153*$G$66:$G$153),"Error") | H4: =SUM(F159:J159) | I4: =E4+F4-G4-H4 | J4: =E159 | K4: =J4-I4 | L4: =+'MERMAS S1'!D5 | N4: =IF(K4<0,K4*L4,0)
D5: Atún Trozos | F5: =E222 | G5: =IFERROR(SUMPRODUCT(($F$66:$F$153="Atún Trozos")*$E$66:$E$153*$G$66:$G$153),"Error") | H5: =SUM(F160:I160)+SUM(F190:I190) | I5: =E5+F5-G5-H5 | J5: =E160+E190 | K5: =J5-I5 | L5: =+'MERMAS S1'!D6 | N5: =IF(K5<0,K5*L5,0)
D6: Almejas Julianas | F6: =E254 | G6: =K254 | H6: =SUM(F161:I161)+J254 | I6: =E6+F6-G6-H6 | J6: =E161 | K6: =J6-I6 | L6: =+'MERMAS S1'!D7 | N6: =IF(K6<0,K6*L6,0)
D7: Carpaccio de res | F7: =E223 | G7: =IFERROR(SUMPRODUCT(($F$66:$F$153="Carpaccio de res")*$E$66:$E$153*$G$66:$G$153),"Error") | H7: =SUM(F162:I162) | I7: =E7+F7-G7-H7 | J7: =E162 | K7: =J7-I7 | L7: =+'MERMAS S1'!D8 | N7: =IF(K7<0,K7*L7,0)
D8: Chupe | F8: =H258 | G8: =E90 | H8: =SUM(F165:I165) | I8: =E8+F8-G8-H8 | J8: =E165 | K8: =J8-I8 | L8: =+'MERMAS S1'!D9 | N8: =IF(K8<0,K8*L8,0)
D9: Congrio | F9: =E252 | G9: =IFERROR(SUMPRODUCT(($F$66:$F$153="Congrio")*$E$66:$E$153*$G$66:$G$153),"Error") | H9: =J252+SUM(F164:I164) | I9: =E9+F9-G9-H9 | J9: =E164 | K9: =J9-I9 | L9: =+'MERMAS S1'!D10 | N9: =IF(K9<0,K9*L9,0)
D10: Filete despunte | F10: =E255 | G10: =K255+K256 | H10: =SUM(J255:J256)+SUM(F167:I167) | I10: =E10+F10-G10-H10 | J10: =E167 | K10: =J10-I10 | L10: =+'MERMAS S1'!D11 | N10: =IF(K10<0,K10*L10,0)
D11: Filete para churrasco | F11: =E226 | G11: =IFERROR(SUMPRODUCT(($F$66:$F$153="Filete para churrasco")*$E$66:$E$153*$G$66:$G$153),"Error") | H11: =SUM(F168:I168) | I11: =E11+F11-G11-H11 | J11: =E168 | K11: =J11-I11 | L11: =+'MERMAS S1'!D12 | N11: =IF(K11<0,K11*L11,0)
D12: Filete para crudo | F12: =E227 | G12: =IFERROR(SUMPRODUCT(($F$66:$F$153="Filete para crudo")*$E$66:$E$153*$G$66:$G$153),"Error") | H12: =SUM(F169:I169)+SUM(F189:I189) | I12: =E12+F12-G12-H12 | J12: =E169 +IFERROR(INDEX($E$159:$E$215,MATCH("Tartar de Res",$D$159:$D$215,0)),0) | K12: =J12-I12 | L12: =+'MERMAS S1'!D13 | N12: =IF(K12<0,K12*L12,0)
D13: Filete Salteado | F13: =E228 | G13: =IFERROR(SUMPRODUCT(($F$66:$F$153=D13)*$E$66:$E$153*$G$66:$G$153),"Error") | H13: =SUM(F170:I170) | I13: =E13+F13-G13-H13 | J13: =E170 | K13: =J13-I13 | L13: =+'MERMAS S1'!D14 | N13: =IF(K13<0,K13*L13,0)
D14: Ganso | F14: =E229 | G14: =IFERROR(SUMPRODUCT(($F$66:$F$153=D14)*$E$66:$E$153*$G$66:$G$153),"Error") | H14: =SUM(F171:I171)+SUM(F180:I180) | I14: =E14+F14-G14-H14 | J14: =E171 +IFERROR(INDEX($E$159:$E$215,MATCH("Paila de Carne",$D$159:$D$215,0)),0) | K14: =J14-I14 | L14: =+'MERMAS S1'!D15 | N14: =IF(K14<0,K14*L14,0)
D15: Hamburguesas | F15: =E231 | G15: =IFERROR(SUMPRODUCT(($F$66:$F$153=D15)*$E$66:$E$153*$G$66:$G$153),"Error") | H15: =SUM(F172:I172) | I15: =E15+F15-G15-H15 | J15: =E172 | K15: =J15-I15 | L15: =+'MERMAS S1'!D16 | N15: =IF(K15<0,K15*L15,0)
D16: Jamón serrano | F16: =E232 | G16: =IFERROR(SUMPRODUCT(($F$66:$F$153=D16)*$E$66:$E$153*$G$66:$G$153),"Error") | H16: =SUM(F174:I174) | I16: =E16+F16-G16-H16 | J16: =E174 | K16: =J16-I16 | L16: =+'MERMAS S1'!D17 | N16: =IF(K16<0,K16*L16,0)
D17: Langostinos | F17: =H248 | G17: =IFERROR(SUMPRODUCT(($F$66:$F$153=D17)*$E$66:$E$153*$G$66:$G$153),"Error") | H17: =SUM(F173:I173) | I17: =E17+F17-G17-H17 | J17: =E173 | K17: =J17-I17 | L17: =+'MERMAS S1'!D18 | N17: =IF(K17<0,K17*L17,0)
D18: Lasagna de Berenjenas | F18: =H257 | G18: =E120 | H18: =SUM(F175:I175) | I18: =E18+F18-G18-H18 | J18: =E175 | K18: =J18-I18 | L18: =+'MERMAS S1'!D19 | N18: =IF(K18<0,K18*L18,0)
D19: Locos | F19: =E249 | G19: =IFERROR(SUMPRODUCT(($F$66:$F$153=D19)*$E$66:$E$153*$G$66:$G$153),"Error") | H19: =SUM(F177:I177)+J249 | I19: =E19+F19-G19-H19 | J19: =E177 | K19: =J19-I19 | L19: =+'MERMAS S1'!D20 | N19: =IF(K19<0,K19*L19,0)
D20: Lomo liso | F20: =E233 | G20: =IFERROR(SUMPRODUCT(($F$66:$F$153=D20)*$E$66:$E$153*$G$66:$G$153),"Error") | H20: =SUM(F176:I176) | I20: =E20+F20-G20-H20 | J20: =E176 | K20: =J20-I20 | L20: =+'MERMAS S1'!D21 | N20: =IF(K20<0,K20*L20,0)
D21: Mejillones | F21: =E253 | G21: =K253 | H21: =J253+SUM(F178:I178) | I21: =E21+F21-G21-H21 | J21: =E178 | K21: =J21-I21 | L21: =+'MERMAS S1'!D22 | N21: =IF(K21<0,K21*L21,0)
D22: Merluza | F22: =E250 | G22: =IFERROR(SUMPRODUCT(($F$66:$F$153=D22)*$E$66:$E$153*$G$66:$G$153),"Error") | H22: =SUM(F179:I179)+J250 | I22: =E22+F22-G22-H22 | J22: =E179 | K22: =J22-I22 | L22: =+'MERMAS S1'!D23 | N22: =IF(K22<0,K22*L22,0)
D23: Plateada | F23: =E234 | G23: =IFERROR(SUMPRODUCT(($F$66:$F$153=D23)*$E$66:$E$153*$G$66:$G$153),"Error") | H23: =SUM(F181:I181) | I23: =E23+F23-G23-H23 | J23: =E181 | K23: =J23-I23 | L23: =+'MERMAS S1'!D24 | N23: =IF(K23<0,K23*L23,0)
D24: Pulpo | F24: =E235 | G24: =IFERROR(SUMPRODUCT(($F$66:$F$153=D24)*$E$66:$E$153*$G$66:$G$153),"Error") | H24: =SUM(F182:I182) | I24: =E24+F24-G24-H24 | J24: =E182 | K24: =J24-I24 | L24: =+'MERMAS S1'!D25 | N24: =IF(K24<0,K24*L24,0)
D25: Ragout Lasagna | F25: =H255 | G25: =E257 | H25: =SUM(F183:I183)+J257 | I25: =E25+F25-G25-H25 | J25: =E183 | K25: =J25-I25 | L25: =+'MERMAS S1'!D26 | N25: =IF(K25<0,K25*L25,0)
D26: Ragout Rigatoni | F26: =H256 | G26: =E133 | H26: =SUM(F184:I184) | I26: =E26+F26-G26-H26 | J26: =E184 | K26: =J26-I26 | L26: =+'MERMAS S1'!D27 | N26: =IF(K26<0,K26*L26,0)
D27: Reineta | F27: =E251 | G27: =IFERROR(SUMPRODUCT(($F$66:$F$153=D27)*$E$66:$E$153*$G$66:$G$153),"Error") | H27: =SUM(F163:I163)+J251 | I27: =E27+F27-G27-H27 | J27: =E163 | K27: =J27-I27 | L27: =+'MERMAS S1'!D28 | N27: =IF(K27<0,K27*L27,0)
D28: Salmón ahumado en frío | F28: =E258 | G28: =K258 | H28: =J258 | I28: =E28+F28-G28-H28 | J28: =E185 | K28: =J28-I28 | L28: =+'MERMAS S1'!D29 | N28: =IF(K28<0,K28*L28,0)
D29: Salmón ahumado en Caliente | F29: =E237 | G29: =IFERROR(SUMPRODUCT(($F$66:$F$153=D29)*$E$66:$E$153*$G$66:$G$153),"Error") | H29: =SUM(F186:I186) | I29: =E29+F29-G29-H29 | J29: =E186 | K29: =J29-I29 | L29: =+'MERMAS S1'!D30 | N29: =IF(K29<0,K29*L29,0)
D30: Salmón cancato | F30: =E238 | G30: =IFERROR(SUMPRODUCT(($F$66:$F$153=D30)*$E$66:$E$153*$G$66:$G$153),"Error") | H30: =SUM(F187:I187) | I30: =E30+F30-G30-H30 | J30: =E187 | K30: =J30-I30 | L30: =+'MERMAS S1'!D31 | N30: =IF(K30<0,K30*L30,0)
D31: Salmón fresco premium | F31: =E239 | G31: =IFERROR(SUMPRODUCT(($F$66:$F$153=D31)*$E$66:$E$153*$G$66:$G$153),"Error") | H31: =SUM(F188:I188) | I31: =E31+F31-G31-H31 | J31: =E188 | K31: =J31-I31 | L31: =+'MERMAS S1'!D32 | N31: =IF(K31<0,K31*L31,0)
I33: DIFERENCIAS PROMEDIO | K33: =SUM(K7:K31) | M33: DCTO. TOTAL | N33: =SUM(N7:N31)
F35: + | G35: (-) | H35: (-) | I35: = | J35: = | K35: = | L35: $ | N35: $
D36: PRODUCTOS | F36: Entregas | G36: Ventas | H36: Mermas | I36: Stock Real | J36: Stock Informado | K36: Diferencias | L36: Precio | N36: Descuento
D37: Brownie Nutella | F37: =E264 | G37: =IFERROR(SUMPRODUCT(($F$66:$F$153=D37)*$E$66:$E$153*$G$66:$G$153),"Error") | H37: =SUM(F194:I194) | I37: =E37+F37-G37-H37 | J37: =E194 | K37: =J37-I37 | L37: =+'MERMAS S1'!D33 | N37: =IF(K37<0,K37*L37,0)
D38: Brownie Vegano | F38: =E265 | G38: =IFERROR(SUMPRODUCT(($F$66:$F$153=D38)*$E$66:$E$153*$G$66:$G$153),"Error") | H38: =SUM(F195:I195) | I38: =E38+F38-G38-H38 | J38: =E195 | K38: =J38-I38 | L38: =+'MERMAS S1'!D34 | N38: =IF(K38<0,K38*L38,0)
D39: Cheesecake de Berries | F39: =E262 | G39: =IFERROR(SUMPRODUCT(($F$66:$F$153="Cheesecake Berries")*$E$66:$E$153*$G$66:$G$153),"Error") | H39: =SUM(F196:I196) | I39: =E39+F39-G39-H39 | J39: =E196 | K39: =J39-I39 | L39: =+'MERMAS S1'!D35 | N39: =IF(K39<0,K39*L39,0)
D40: Cheesecake de Limón | F40: =E263 | G40: =IFERROR(SUMPRODUCT(($F$66:$F$153=D40)*$E$66:$E$153*$G$66:$G$153),"Error") | H40: =SUM(F197:H197) | I40: =E40+F40-G40-H40 | J40: =E197 | K40: =J40-I40 | L40: =+'MERMAS S1'!D36 | N40: =IF(K40<0,K40*L40,0)
D41: Chocolate Blanco | F41: =H262 | G41: =J262 | H41: =SUM(F198:I198) | I41: =E41+F41-G41-H41 | J41: =E198 | K41: =J41-I41 | L41: =+'MERMAS S1'!D37 | N41: =IF(K41<0,K41*L41,0)
D42: Chocolate Leche | F42: =H263 | G42: =J263 | H42: =SUM(F199:I199) | I42: =E42+F42-G42-H42 | J42: =E199 | K42: =J42-I42 | L42: =+'MERMAS S1'!D38 | N42: =IF(K42<0,K42*L42,0)
D43: Chocolate Negro | F43: =H264 | G43: =J264 | H43: =SUM(F200:I200) | I43: =E43+F43-G43-H43 | J43: =E200 | K43: =J43-I43 | L43: =+'MERMAS S1'!D39 | N43: =IF(K43<0,K43*L43,0)
...

Sheet S1 Jueves
D2: PRODUCTOS | E2: + | F2: + | G2: (-) | H2: (-) | I2: = | J2: = | K2: = | L2: $ | N2: $
E3: Stock Inicial | F3: Entregas | G3: Ventas | H3: Mermas | I3: Stock Real | J3: Stock Informado | K3: Diferencias | L3: Precio | N3: Descuento
D4: Atún Steak | F4: =E221 | G4: =IFERROR(SUMPRODUCT(($F$66:$F$153="Atún Steak")*$E$66:$E$153*$G$66:$G$153),"Error") | H4: =SUM(F159:J159) | I4: =E4+F4-G4-H4 | J4: =E159 | K4: =J4-I4 | L4: =+'MERMAS S1'!D5 | N4: =IF(K4<0,K4*L4,0)
D5: Atún Trozos | F5: =E222 | G5: =IFERROR(SUMPRODUCT(($F$66:$F$153="Atún Trozos")*$E$66:$E$153*$G$66:$G$153),"Error") | H5: =SUM(F160:I160)+SUM(F190:I190) | I5: =E5+F5-G5-H5 | J5: =E160+E190 | K5: =J5-I5 | L5: =+'MERMAS S1'!D6 | N5: =IF(K5<0,K5*L5,0)
D6: Almejas Julianas | F6: =E254 | G6: =K254 | H6: =SUM(F161:I161)+J254 | I6: =E6+F6-G6-H6 | J6: =E161 | K6: =J6-I6 | L6: =+'MERMAS S1'!D7 | N6: =IF(K6<0,K6*L6,0)
D7: Carpaccio de res | F7: =E223 | G7: =IFERROR(SUMPRODUCT(($F$66:$F$153="Carpaccio de res")*$E$66:$E$153*$G$66:$G$153),"Error") | H7: =SUM(F162:I162) | I7: =E7+F7-G7-H7 | J7: =E162 | K7: =J7-I7 | L7: =+'MERMAS S1'!D8 | N7: =IF(K7<0,K7*L7,0)
D8: Chupe | F8: =H258 | G8: =E90 | H8: =SUM(F165:I165) | I8: =E8+F8-G8-H8 | J8: =E165 | K8: =J8-I8 | L8: =+'MERMAS S1'!D9 | N8: =IF(K8<0,K8*L8,0)
D9: Congrio | F9: =E252 | G9: =IFERROR(SUMPRODUCT(($F$66:$F$153="Congrio")*$E$66:$E$153*$G$66:$G$153),"Error") | H9: =J252+SUM(F164:I164) | I9: =E9+F9-G9-H9 | J9: =E164 | K9: =J9-I9 | L9: =+'MERMAS S1'!D10 | N9: =IF(K9<0,K9*L9,0)
D10: Filete despunte | F10: =E255 | G10: =K255+K256 | H10: =SUM(J255:J256)+SUM(F167:I167) | I10: =E10+F10-G10-H10 | J10: =E167 | K10: =J10-I10 | L10: =+'MERMAS S1'!D11 | N10: =IF(K10<0,K10*L10,0)
D11: Filete para churrasco | F11: =E226 | G11: =IFERROR(SUMPRODUCT(($F$66:$F$153="Filete para churrasco")*$E$66:$E$153*$G$66:$G$153),"Error") | H11: =SUM(F168:I168) | I11: =E11+F11-G11-H11 | J11: =E168 | K11: =J11-I11 | L11: =+'MERMAS S1'!D12 | N11: =IF(K11<0,K11*L11,0)
D12: Filete para crudo | F12: =E227 | G12: =IFERROR(SUMPRODUCT(($F$66:$F$153="Filete para crudo")*$E$66:$E$153*$G$66:$G$153),"Error") | H12: =SUM(F169:I169)+SUM(F189:I189) | I12: =E12+F12-G12-H12 | J12: =E169 +IFERROR(INDEX($E$159:$E$215,MATCH("Tartar de Res",$D$159:$D$215,0)),0) | K12: =J12-I12 | L12: =+'MERMAS S1'!D13 | N12: =IF(K12<0,K12*L12,0)
D13: Filete Salteado | F13: =E228 | G13: =IFERROR(SUMPRODUCT(($F$66:$F$153=D13)*$E$66:$E$153*$G$66:$G$153),"Error") | H13: =SUM(F170:I170) | I13: =E13+F13-G13-H13 | J13: =E170 | K13: =J13-I13 | L13: =+'MERMAS S1'!D14 | N13: =IF(K13<0,K13*L13,0)
D14: Ganso | F14: =E229 | G14: =IFERROR(SUMPRODUCT(($F$66:$F$153=D14)*$E$66:$E$153*$G$66:$G$153),"Error") | H14: =SUM(F171:I171)+SUM(F180:I180) | I14: =E14+F14-G14-H14 | J14: =E171 +IFERROR(INDEX($E$159:$E$215,MATCH("Paila de Carne",$D$159:$D$215,0)),0) | K14: =J14-I14 | L14: =+'MERMAS S1'!D15 | N14: =IF(K14<0,K14*L14,0)
D15: Hamburguesas | F15: =E231 | G15: =IFERROR(SUMPRODUCT(($F$66:$F$153=D15)*$E$66:$E$153*$G$66:$G$153),"Error") | H15: =SUM(F172:I172) | I15: =E15+F15-G15-H15 | J15: =E172 | K15: =J15-I15 | L15: =+'MERMAS S1'!D16 | N15: =IF(K15<0,K15*L15,0)
D16: Jamón serrano | F16: =E232 | G16: =IFERROR(SUMPRODUCT(($F$66:$F$153=D16)*$E$66:$E$153*$G$66:$G$153),"Error") | H16: =SUM(F174:I174) | I16: =E16+F16-G16-H16 | J16: =E174 | K16: =J16-I16 | L16: =+'MERMAS S1'!D17 | N16: =IF(K16<0,K16*L16,0)
D17: Langostinos | F17: =H248 | G17: =IFERROR(SUMPRODUCT(($F$66:$F$153=D17)*$E$66:$E$153*$G$66:$G$153),"Error") | H17: =SUM(F173:I173) | I17: =E17+F17-G17-H17 | J17: =E173 | K17: =J17-I17 | L17: =+'MERMAS S1'!D18 | N17: =IF(K17<0,K17*L17,0)
D18: Lasagna de Berenjenas | F18: =H257 | G18: =E120 | H18: =SUM(F175:I175) | I18: =E18+F18-G18-H18 | J18: =E175 | K18: =J18-I18 | L18: =+'MERMAS S1'!D19 | N18: =IF(K18<0,K18*L18,0)
D19: Locos | F19: =E249 | G19: =IFERROR(SUMPRODUCT(($F$66:$F$153=D19)*$E$66:$E$153*$G$66:$G$153),"Error") | H19: =SUM(F177:I177)+J249 | I19: =E19+F19-G19-H19 | J19: =E177 | K19: =J19-I19 | L19: =+'MERMAS S1'!D20 | N19: =IF(K19<0,K19*L19,0)
D20: Lomo liso | F20: =E233 | G20: =IFERROR(SUMPRODUCT(($F$66:$F$153=D20)*$E$66:$E$153*$G$66:$G$153),"Error") | H20: =SUM(F176:I176) | I20: =E20+F20-G20-H20 | J20: =E176 | K20: =J20-I20 | L20: =+'MERMAS S1'!D21 | N20: =IF(K20<0,K20*L20,0)
D21: Mejillones | F21: =E253 | G21: =K253 | H21: =J253+SUM(F178:I178) | I21: =E21+F21-G21-H21 | J21: =E178 | K21: =J21-I21 | L21: =+'MERMAS S1'!D22 | N21: =IF(K21<0,K21*L21,0)
D22: Merluza | F22: =E250 | G22: =IFERROR(SUMPRODUCT(($F$66:$F$153=D22)*$E$66:$E$153*$G$66:$G$153),"Error") | H22: =SUM(F179:I179)+J250 | I22: =E22+F22-G22-H22 | J22: =E179 | K22: =J22-I22 | L22: =+'MERMAS S1'!D23 | N22: =IF(K22<0,K22*L22,0)
D23: Plateada | F23: =E234 | G23: =IFERROR(SUMPRODUCT(($F$66:$F$153=D23)*$E$66:$E$153*$G$66:$G$153),"Error") | H23: =SUM(F181:I181) | I23: =E23+F23-G23-H23 | J23: =E181 | K23: =J23-I23 | L23: =+'MERMAS S1'!D24 | N23: =IF(K23<0,K23*L23,0)
D24: Pulpo | F24: =E235 | G24: =IFERROR(SUMPRODUCT(($F$66:$F$153=D24)*$E$66:$E$153*$G$66:$G$153),"Error") | H24: =SUM(F182:I182) | I24: =E24+F24-G24-H24 | J24: =E182 | K24: =J24-I24 | L24: =+'MERMAS S1'!D25 | N24: =IF(K24<0,K24*L24,0)
D25: Ragout Lasagna | F25: =H255 | G25: =E257 | H25: =SUM(F183:I183)+J257 | I25: =E25+F25-G25-H25 | J25: =E183 | K25: =J25-I25 | L25: =+'MERMAS S1'!D26 | N25: =IF(K25<0,K25*L25,0)
D26: Ragout Rigatoni | F26: =H256 | G26: =E133 | H26: =SUM(F184:I184) | I26: =E26+F26-G26-H26 | J26: =E184 | K26: =J26-I26 | L26: =+'MERMAS S1'!D27 | N26: =IF(K26<0,K26*L26,0)
D27: Reineta | F27: =E251 | G27: =IFERROR(SUMPRODUCT(($F$66:$F$153=D27)*$E$66:$E$153*$G$66:$G$153),"Error") | H27: =SUM(F163:I163)+J251 | I27: =E27+F27-G27-H27 | J27: =E163 | K27: =J27-I27 | L27: =+'MERMAS S1'!D28 | N27: =IF(K27<0,K27*L27,0)
D28: Salmón ahumado en frío | F28: =E258 | G28: =K258 | H28: =J258 | I28: =E28+F28-G28-H28 | J28: =E185 | K28: =J28-I28 | L28: =+'MERMAS S1'!D29 | N28: =IF(K28<0,K28*L28,0)
D29: Salmón ahumado en Caliente | F29: =E237 | G29: =IFERROR(SUMPRODUCT(($F$66:$F$153=D29)*$E$66:$E$153*$G$66:$G$153),"Error") | H29: =SUM(F186:I186) | I29: =E29+F29-G29-H29 | J29: =E186 | K29: =J29-I29 | L29: =+'MERMAS S1'!D30 | N29: =IF(K29<0,K29*L29,0)
D30: Salmón cancato | F30: =E238 | G30: =IFERROR(SUMPRODUCT(($F$66:$F$153=D30)*$E$66:$E$153*$G$66:$G$153),"Error") | H30: =SUM(F187:I187) | I30: =E30+F30-G30-H30 | J30: =E187 | K30: =J30-I30 | L30: =+'MERMAS S1'!D31 | N30: =IF(K30<0,K30*L30,0)
D31: Salmón fresco premium | F31: =E239 | G31: =IFERROR(SUMPRODUCT(($F$66:$F$153=D31)*$E$66:$E$153*$G$66:$G$153),"Error") | H31: =SUM(F188:I188) | I31: =E31+F31-G31-H31 | J31: =E188 | K31: =J31-I31 | L31: =+'MERMAS S1'!D32 | N31: =IF(K31<0,K31*L31,0)
I33: DIFERENCIAS PROMEDIO | K33: =SUM(K7:K31) | M33: DCTO. TOTAL | N33: =SUM(N7:N31)
F35: + | G35: (-) | H35: (-) | I35: = | J35: = | K35: = | L35: $ | N35: $
D36: PRODUCTOS | F36: Entregas | G36: Ventas | H36: Mermas | I36: Stock Real | J36: Stock Informado | K36: Diferencias | L36: Precio | N36: Descuento
D37: Brownie Nutella | F37: =E264 | G37: =IFERROR(SUMPRODUCT(($F$66:$F$153=D37)*$E$66:$E$153*$G$66:$G$153),"Error") | H37: =SUM(F194:I194) | I37: =E37+F37-G37-H37 | J37: =E194 | K37: =J37-I37 | L37: =+'MERMAS S1'!D33 | N37: =IF(K37<0,K37*L37,0)
D38: Brownie Vegano | F38: =E265 | G38: =IFERROR(SUMPRODUCT(($F$66:$F$153=D38)*$E$66:$E$153*$G$66:$G$153),"Error") | H38: =SUM(F195:I195) | I38: =E38+F38-G38-H38 | J38: =E195 | K38: =J38-I38 | L38: =+'MERMAS S1'!D34 | N38: =IF(K38<0,K38*L38,0)
D39: Cheesecake de Berries | F39: =E262 | G39: =IFERROR(SUMPRODUCT(($F$66:$F$153="Cheesecake Berries")*$E$66:$E$153*$G$66:$G$153),"Error") | H39: =SUM(F196:I196) | I39: =E39+F39-G39-H39 | J39: =E196 | K39: =J39-I39 | L39: =+'MERMAS S1'!D35 | N39: =IF(K39<0,K39*L39,0)
D40: Cheesecake de Limón | F40: =E263 | G40: =IFERROR(SUMPRODUCT(($F$66:$F$153=D40)*$E$66:$E$153*$G$66:$G$153),"Error") | H40: =SUM(F197:H197) | I40: =E40+F40-G40-H40 | J40: =E197 | K40: =J40-I40 | L40: =+'MERMAS S1'!D36 | N40: =IF(K40<0,K40*L40,0)
D41: Chocolate Blanco | F41: =H262 | G41: =J262 | H41: =SUM(F198:I198) | I41: =E41+F41-G41-H41 | J41: =E198 | K41: =J41-I41 | L41: =+'MERMAS S1'!D37 | N41: =IF(K41<0,K41*L41,0)
D42: Chocolate Leche | F42: =H263 | G42: =J263 | H42: =SUM(F199:I199) | I42: =E42+F42-G42-H42 | J42: =E199 | K42: =J42-I42 | L42: =+'MERMAS S1'!D38 | N42: =IF(K42<0,K42*L42,0)
D43: Chocolate Negro | F43: =H264 | G43: =J264 | H43: =SUM(F200:I200) | I43: =E43+F43-G43-H43 | J43: =E200 | K43: =J43-I43 | L43: =+'MERMAS S1'!D39 | N43: =IF(K43<0,K43*L43,0)
...

Sheet S1 Viernes
D2: PRODUCTOS | E2: + | F2: + | G2: (-) | H2: (-) | I2: = | J2: = | K2: = | L2: $ | N2: $
E3: Stock Inicial | F3: Entregas | G3: Ventas | H3: Mermas | I3: Stock Real | J3: Stock Informado | K3: Diferencias | L3: Precio | N3: Descuento
D4: Atún Steak | F4: =E221 | G4: =IFERROR(SUMPRODUCT(($F$66:$F$153="Atún Steak")*$E$66:$E$153*$G$66:$G$153),"Error") | H4: =SUM(F159:J159) | I4: =E4+F4-G4-H4 | J4: =E159 | K4: =J4-I4 | L4: =+'MERMAS S1'!D5 | N4: =IF(K4<0,K4*L4,0)
D5: Atún Trozos | F5: =E222 | G5: =IFERROR(SUMPRODUCT(($F$66:$F$153="Atún Trozos")*$E$66:$E$153*$G$66:$G$153),"Error") | H5: =SUM(F160:I160)+SUM(F190:I190) | I5: =E5+F5-G5-H5 | J5: =E160+E190 | K5: =J5-I5 | L5: =+'MERMAS S1'!D6 | N5: =IF(K5<0,K5*L5,0)
D6: Almejas Julianas | F6: =E254 | G6: =K254 | H6: =SUM(F161:I161)+J254 | I6: =E6+F6-G6-H6 | J6: =E161 | K6: =J6-I6 | L6: =+'MERMAS S1'!D7 | N6: =IF(K6<0,K6*L6,0)
D7: Carpaccio de res | F7: =E223 | G7: =IFERROR(SUMPRODUCT(($F$66:$F$153="Carpaccio de res")*$E$66:$E$153*$G$66:$G$153),"Error") | H7: =SUM(F162:I162) | I7: =E7+F7-G7-H7 | J7: =E162 | K7: =J7-I7 | L7: =+'MERMAS S1'!D8 | N7: =IF(K7<0,K7*L7,0)
D8: Chupe | F8: =H258 | G8: =E90 | H8: =SUM(F165:I165) | I8: =E8+F8-G8-H8 | J8: =E165 | K8: =J8-I8 | L8: =+'MERMAS S1'!D9 | N8: =IF(K8<0,K8*L8,0)
D9: Congrio | F9: =E252 | G9: =IFERROR(SUMPRODUCT(($F$66:$F$153="Congrio")*$E$66:$E$153*$G$66:$G$153),"Error") | H9: =J252+SUM(F164:I164) | I9: =E9+F9-G9-H9 | J9: =E164 | K9: =J9-I9 | L9: =+'MERMAS S1'!D10 | N9: =IF(K9<0,K9*L9,0)
D10: Filete despunte | F10: =E255 | G10: =K255+K256 | H10: =SUM(J255:J256)+SUM(F167:I167) | I10: =E10+F10-G10-H10 | J10: =E167 | K10: =J10-I10 | L10: =+'MERMAS S1'!D11 | N10: =IF(K10<0,K10*L10,0)
D11: Filete para churrasco | F11: =E226 | G11: =IFERROR(SUMPRODUCT(($F$66:$F$153="Filete para churrasco")*$E$66:$E$153*$G$66:$G$153),"Error") | H11: =SUM(F168:I168) | I11: =E11+F11-G11-H11 | J11: =E168 | K11: =J11-I11 | L11: =+'MERMAS S1'!D12 | N11: =IF(K11<0,K11*L11,0)
D12: Filete para crudo | F12: =E227 | G12: =IFERROR(SUMPRODUCT(($F$66:$F$153="Filete para crudo")*$E$66:$E$153*$G$66:$G$153),"Error") | H12: =SUM(F169:I169)+SUM(F189:I189) | I12: =E12+F12-G12-H12 | J12: =E169 +IFERROR(INDEX($E$159:$E$215,MATCH("Tartar de Res",$D$159:$D$215,0)),0) | K12: =J12-I12 | L12: =+'MERMAS S1'!D13 | N12: =IF(K12<0,K12*L12,0)
D13: Filete Salteado | F13: =E228 | G13: =IFERROR(SUMPRODUCT(($F$66:$F$153=D13)*$E$66:$E$153*$G$66:$G$153),"Error") | H13: =SUM(F170:I170) | I13: =E13+F13-G13-H13 | J13: =E170 | K13: =J13-I13 | L13: =+'MERMAS S1'!D14 | N13: =IF(K13<0,K13*L13,0)
D14: Ganso | F14: =E229 | G14: =IFERROR(SUMPRODUCT(($F$66:$F$153=D14)*$E$66:$E$153*$G$66:$G$153),"Error") | H14: =SUM(F171:I171)+SUM(F180:I180) | I14: =E14+F14-G14-H14 | J14: =E171 +IFERROR(INDEX($E$159:$E$215,MATCH("Paila de Carne",$D$159:$D$215,0)),0) | K14: =J14-I14 | L14: =+'MERMAS S1'!D15 | N14: =IF(K14<0,K14*L14,0)
D15: Hamburguesas | F15: =E231 | G15: =IFERROR(SUMPRODUCT(($F$66:$F$153=D15)*$E$66:$E$153*$G$66:$G$153),"Error") | H15: =SUM(F172:I172) | I15: =E15+F15-G15-H15 | J15: =E172 | K15: =J15-I15 | L15: =+'MERMAS S1'!D16 | N15: =IF(K15<0,K15*L15,0)
D16: Jamón serrano | F16: =E232 | G16: =IFERROR(SUMPRODUCT(($F$66:$F$153=D16)*$E$66:$E$153*$G$66:$G$153),"Error") | H16: =SUM(F174:I174) | I16: =E16+F16-G16-H16 | J16: =E174 | K16: =J16-I16 | L16: =+'MERMAS S1'!D17 | N16: =IF(K16<0,K16*L16,0)
D17: Langostinos | F17: =H248 | G17: =IFERROR(SUMPRODUCT(($F$66:$F$153=D17)*$E$66:$E$153*$G$66:$G$153),"Error") | H17: =SUM(F173:I173) | I17: =E17+F17-G17-H17 | J17: =E173 | K17: =J17-I17 | L17: =+'MERMAS S1'!D18 | N17: =IF(K17<0,K17*L17,0)
D18: Lasagna de Berenjenas | F18: =H257 | G18: =E120 | H18: =SUM(F175:I175) | I18: =E18+F18-G18-H18 | J18: =E175 | K18: =J18-I18 | L18: =+'MERMAS S1'!D19 | N18: =IF(K18<0,K18*L18,0)
D19: Locos | F19: =E249 | G19: =IFERROR(SUMPRODUCT(($F$66:$F$153=D19)*$E$66:$E$153*$G$66:$G$153),"Error") | H19: =SUM(F177:I177)+J249 | I19: =E19+F19-G19-H19 | J19: =E177 | K19: =J19-I19 | L19: =+'MERMAS S1'!D20 | N19: =IF(K19<0,K19*L19,0)
D20: Lomo liso | F20: =E233 | G20: =IFERROR(SUMPRODUCT(($F$66:$F$153=D20)*$E$66:$E$153*$G$66:$G$153),"Error") | H20: =SUM(F176:I176) | I20: =E20+F20-G20-H20 | J20: =E176 | K20: =J20-I20 | L20: =+'MERMAS S1'!D21 | N20: =IF(K20<0,K20*L20,0)
D21: Mejillones | F21: =E253 | G21: =K253 | H21: =J253+SUM(F178:I178) | I21: =E21+F21-G21-H21 | J21: =E178 | K21: =J21-I21 | L21: =+'MERMAS S1'!D22 | N21: =IF(K21<0,K21*L21,0)
D22: Merluza | F22: =E250 | G22: =IFERROR(SUMPRODUCT(($F$66:$F$153=D22)*$E$66:$E$153*$G$66:$G$153),"Error") | H22: =SUM(F179:I179)+J250 | I22: =E22+F22-G22-H22 | J22: =E179 | K22: =J22-I22 | L22: =+'MERMAS S1'!D23 | N22: =IF(K22<0,K22*L22,0)
D23: Plateada | F23: =E234 | G23: =IFERROR(SUMPRODUCT(($F$66:$F$153=D23)*$E$66:$E$153*$G$66:$G$153),"Error") | H23: =SUM(F181:I181) | I23: =E23+F23-G23-H23 | J23: =E181 | K23: =J23-I23 | L23: =+'MERMAS S1'!D24 | N23: =IF(K23<0,K23*L23,0)
D24: Pulpo | F24: =E235 | G24: =IFERROR(SUMPRODUCT(($F$66:$F$153=D24)*$E$66:$E$153*$G$66:$G$153),"Error") | H24: =SUM(F182:I182) | I24: =E24+F24-G24-H24 | J24: =E182 | K24: =J24-I24 | L24: =+'MERMAS S1'!D25 | N24: =IF(K24<0,K24*L24,0)
D25: Ragout Lasagna | F25: =H255 | G25: =E257 | H25: =SUM(F183:I183)+J257 | I25: =E25+F25-G25-H25 | J25: =E183 | K25: =J25-I25 | L25: =+'MERMAS S1'!D26 | N25: =IF(K25<0,K25*L25,0)
D26: Ragout Rigatoni | F26: =H256 | G26: =E133 | H26: =SUM(F184:I184) | I26: =E26+F26-G26-H26 | J26: =E184 | K26: =J26-I26 | L26: =+'MERMAS S1'!D27 | N26: =IF(K26<0,K26*L26,0)
D27: Reineta | F27: =E251 | G27: =IFERROR(SUMPRODUCT(($F$66:$F$153=D27)*$E$66:$E$153*$G$66:$G$153),"Error") | H27: =SUM(F163:I163)+J251 | I27: =E27+F27-G27-H27 | J27: =E163 | K27: =J27-I27 | L27: =+'MERMAS S1'!D28 | N27: =IF(K27<0,K27*L27,0)
D28: Salmón ahumado en frío | F28: =E258 | G28: =K258 | H28: =J258 | I28: =E28+F28-G28-H28 | J28: =E185 | K28: =J28-I28 | L28: =+'MERMAS S1'!D29 | N28: =IF(K28<0,K28*L28,0)
D29: Salmón ahumado en Caliente | F29: =E237 | G29: =IFERROR(SUMPRODUCT(($F$66:$F$153=D29)*$E$66:$E$153*$G$66:$G$153),"Error") | H29: =SUM(F186:I186) | I29: =E29+F29-G29-H29 | J29: =E186 | K29: =J29-I29 | L29: =+'MERMAS S1'!D30 | N29: =IF(K29<0,K29*L29,0)
D30: Salmón cancato | F30: =E238 | G30: =IFERROR(SUMPRODUCT(($F$66:$F$153=D30)*$E$66:$E$153*$G$66:$G$153),"Error") | H30: =SUM(F187:I187) | I30: =E30+F30-G30-H30 | J30: =E187 | K30: =J30-I30 | L30: =+'MERMAS S1'!D31 | N30: =IF(K30<0,K30*L30,0)
D31: Salmón fresco premium | F31: =E239 | G31: =IFERROR(SUMPRODUCT(($F$66:$F$153=D31)*$E$66:$E$153*$G$66:$G$153),"Error") | H31: =SUM(F188:I188) | I31: =E31+F31-G31-H31 | J31: =E188 | K31: =J31-I31 | L31: =+'MERMAS S1'!D32 | N31: =IF(K31<0,K31*L31,0)
I33: DIFERENCIAS PROMEDIO | K33: =SUM(K7:K31) | M33: DCTO. TOTAL | N33: =SUM(N7:N31)
F35: + | G35: (-) | H35: (-) | I35: = | J35: = | K35: = | L35: $ | N35: $
D36: PRODUCTOS | F36: Entregas | G36: Ventas | H36: Mermas | I36: Stock Real | J36: Stock Informado | K36: Diferencias | L36: Precio | N36: Descuento
D37: Brownie Nutella | F37: =E264 | G37: =IFERROR(SUMPRODUCT(($F$66:$F$153=D37)*$E$66:$E$153*$G$66:$G$153),"Error") | H37: =SUM(F194:I194) | I37: =E37+F37-G37-H37 | J37: =E194 | K37: =J37-I37 | L37: =+'MERMAS S1'!D33 | N37: =IF(K37<0,K37*L37,0)
D38: Brownie Vegano | F38: =E265 | G38: =IFERROR(SUMPRODUCT(($F$66:$F$153=D38)*$E$66:$E$153*$G$66:$G$153),"Error") | H38: =SUM(F195:I195) | I38: =E38+F38-G38-H38 | J38: =E195 | K38: =J38-I38 | L38: =+'MERMAS S1'!D34 | N38: =IF(K38<0,K38*L38,0)
D39: Cheesecake de Berries | F39: =E262 | G39: =IFERROR(SUMPRODUCT(($F$66:$F$153="Cheesecake Berries")*$E$66:$E$153*$G$66:$G$153),"Error") | H39: =SUM(F196:I196) | I39: =E39+F39-G39-H39 | J39: =E196 | K39: =J39-I39 | L39: =+'MERMAS S1'!D35 | N39: =IF(K39<0,K39*L39,0)
D40: Cheesecake de Limón | F40: =E263 | G40: =IFERROR(SUMPRODUCT(($F$66:$F$153=D40)*$E$66:$E$153*$G$66:$G$153),"Error") | H40: =SUM(F197:H197) | I40: =E40+F40-G40-H40 | J40: =E197 | K40: =J40-I40 | L40: =+'MERMAS S1'!D36 | N40: =IF(K40<0,K40*L40,0)
D41: Chocolate Blanco | F41: =H262 | G41: =J262 | H41: =SUM(F198:I198) | I41: =E41+F41-G41-H41 | J41: =E198 | K41: =J41-I41 | L41: =+'MERMAS S1'!D37 | N41: =IF(K41<0,K41*L41,0)
D42: Chocolate Leche | F42: =H263 | G42: =J263 | H42: =SUM(F199:I199) | I42: =E42+F42-G42-H42 | J42: =E199 | K42: =J42-I42 | L42: =+'MERMAS S1'!D38 | N42: =IF(K42<0,K42*L42,0)
D43: Chocolate Negro | F43: =H264 | G43: =J264 | H43: =SUM(F200:I200) | I43: =E43+F43-G43-H43 | J43: =E200 | K43: =J43-I43 | L43: =+'MERMAS S1'!D39 | N43: =IF(K43<0,K43*L43,0)
...

Sheet S1 Sábado
D2: PRODUCTOS | E2: + | F2: + | G2: (-) | H2: (-) | I2: = | J2: = | K2: = | L2: $ | N2: $
E3: Stock Inicial | F3: Entregas | G3: Ventas | H3: Mermas | I3: Stock Real | J3: Stock Informado | K3: Diferencias | L3: Precio | N3: Descuento
D4: Atún Steak | F4: =E221 | G4: =IFERROR(SUMPRODUCT(($F$66:$F$153="Atún Steak")*$E$66:$E$153*$G$66:$G$153),"Error") | H4: =SUM(F159:J159) | I4: =E4+F4-G4-H4 | J4: =E159 | K4: =J4-I4 | L4: =+'MERMAS S1'!D5 | N4: =IF(K4<0,K4*L4,0)
D5: Atún Trozos | F5: =E222 | G5: =IFERROR(SUMPRODUCT(($F$66:$F$153="Atún Trozos")*$E$66:$E$153*$G$66:$G$153),"Error") | H5: =SUM(F160:I160)+SUM(F190:I190) | I5: =E5+F5-G5-H5 | J5: =E160+E190 | K5: =J5-I5 | L5: =+'MERMAS S1'!D6 | N5: =IF(K5<0,K5*L5,0)
D6: Almejas Julianas | F6: =E254 | G6: =K254 | H6: =SUM(F161:I161)+J254 | I6: =E6+F6-G6-H6 | J6: =E161 | K6: =J6-I6 | L6: =+'MERMAS S1'!D7 | N6: =IF(K6<0,K6*L6,0)
D7: Carpaccio de res | F7: =E223 | G7: =IFERROR(SUMPRODUCT(($F$66:$F$153="Carpaccio de res")*$E$66:$E$153*$G$66:$G$153),"Error") | H7: =SUM(F162:I162) | I7: =E7+F7-G7-H7 | J7: =E162 | K7: =J7-I7 | L7: =+'MERMAS S1'!D8 | N7: =IF(K7<0,K7*L7,0)
D8: Chupe | F8: =H258 | G8: =E90 | H8: =SUM(F165:I165) | I8: =E8+F8-G8-H8 | J8: =E165 | K8: =J8-I8 | L8: =+'MERMAS S1'!D9 | N8: =IF(K8<0,K8*L8,0)
D9: Congrio | F9: =E252 | G9: =IFERROR(SUMPRODUCT(($F$66:$F$153="Congrio")*$E$66:$E$153*$G$66:$G$153),"Error") | H9: =J252+SUM(F164:I164) | I9: =E9+F9-G9-H9 | J9: =E164 | K9: =J9-I9 | L9: =+'MERMAS S1'!D10 | N9: =IF(K9<0,K9*L9,0)
D10: Filete despunte | F10: =E255 | G10: =K255+K256 | H10: =SUM(J255:J256)+SUM(F167:I167) | I10: =E10+F10-G10-H10 | J10: =E167 | K10: =J10-I10 | L10: =+'MERMAS S1'!D11 | N10: =IF(K10<0,K10*L10,0)
D11: Filete para churrasco | F11: =E226 | G11: =IFERROR(SUMPRODUCT(($F$66:$F$153="Filete para churrasco")*$E$66:$E$153*$G$66:$G$153),"Error") | H11: =SUM(F168:I168) | I11: =E11+F11-G11-H11 | J11: =E168 | K11: =J11-I11 | L11: =+'MERMAS S1'!D12 | N11: =IF(K11<0,K11*L11,0)
D12: Filete para crudo | F12: =E227 | G12: =IFERROR(SUMPRODUCT(($F$66:$F$153="Filete para crudo")*$E$66:$E$153*$G$66:$G$153),"Error") | H12: =SUM(F169:I169)+SUM(F189:I189) | I12: =E12+F12-G12-H12 | J12: =E169 +IFERROR(INDEX($E$159:$E$215,MATCH("Tartar de Res",$D$159:$D$215,0)),0) | K12: =J12-I12 | L12: =+'MERMAS S1'!D13 | N12: =IF(K12<0,K12*L12,0)
D13: Filete Salteado | F13: =E228 | G13: =IFERROR(SUMPRODUCT(($F$66:$F$153=D13)*$E$66:$E$153*$G$66:$G$153),"Error") | H13: =SUM(F170:I170) | I13: =E13+F13-G13-H13 | J13: =E170 | K13: =J13-I13 | L13: =+'MERMAS S1'!D14 | N13: =IF(K13<0,K13*L13,0)
D14: Ganso | F14: =E229 | G14: =IFERROR(SUMPRODUCT(($F$66:$F$153=D14)*$E$66:$E$153*$G$66:$G$153),"Error") | H14: =SUM(F171:I171)+SUM(F180:I180) | I14: =E14+F14-G14-H14 | J14: =E171 +IFERROR(INDEX($E$159:$E$215,MATCH("Paila de Carne",$D$159:$D$215,0)),0) | K14: =J14-I14 | L14: =+'MERMAS S1'!D15 | N14: =IF(K14<0,K14*L14,0)
D15: Hamburguesas | F15: =E231 | G15: =IFERROR(SUMPRODUCT(($F$66:$F$153=D15)*$E$66:$E$153*$G$66:$G$153),"Error") | H15: =SUM(F172:I172) | I15: =E15+F15-G15-H15 | J15: =E172 | K15: =J15-I15 | L15: =+'MERMAS S1'!D16 | N15: =IF(K15<0,K15*L15,0)
D16: Jamón serrano | F16: =E232 | G16: =IFERROR(SUMPRODUCT(($F$66:$F$153=D16)*$E$66:$E$153*$G$66:$G$153),"Error") | H16: =SUM(F174:I174) | I16: =E16+F16-G16-H16 | J16: =E174 | K16: =J16-I16 | L16: =+'MERMAS S1'!D17 | N16: =IF(K16<0,K16*L16,0)
D17: Langostinos | F17: =H248 | G17: =IFERROR(SUMPRODUCT(($F$66:$F$153=D17)*$E$66:$E$153*$G$66:$G$153),"Error") | H17: =SUM(F173:I173) | I17: =E17+F17-G17-H17 | J17: =E173 | K17: =J17-I17 | L17: =+'MERMAS S1'!D18 | N17: =IF(K17<0,K17*L17,0)
D18: Lasagna de Berenjenas | F18: =H257 | G18: =E120 | H18: =SUM(F175:I175) | I18: =E18+F18-G18-H18 | J18: =E175 | K18: =J18-I18 | L18: =+'MERMAS S1'!D19 | N18: =IF(K18<0,K18*L18,0)
D19: Locos | F19: =E249 | G19: =IFERROR(SUMPRODUCT(($F$66:$F$153=D19)*$E$66:$E$153*$G$66:$G$153),"Error") | H19: =SUM(F177:I177)+J249 | I19: =E19+F19-G19-H19 | J19: =E177 | K19: =J19-I19 | L19: =+'MERMAS S1'!D20 | N19: =IF(K19<0,K19*L19,0)
D20: Lomo liso | F20: =E233 | G20: =IFERROR(SUMPRODUCT(($F$66:$F$153=D20)*$E$66:$E$153*$G$66:$G$153),"Error") | H20: =SUM(F176:I176) | I20: =E20+F20-G20-H20 | J20: =E176 | K20: =J20-I20 | L20: =+'MERMAS S1'!D21 | N20: =IF(K20<0,K20*L20,0)
D21: Mejillones | F21: =E253 | G21: =K253 | H21: =J253+SUM(F178:I178) | I21: =E21+F21-G21-H21 | J21: =E178 | K21: =J21-I21 | L21: =+'MERMAS S1'!D22 | N21: =IF(K21<0,K21*L21,0)
D22: Merluza | F22: =E250 | G22: =IFERROR(SUMPRODUCT(($F$66:$F$153=D22)*$E$66:$E$153*$G$66:$G$153),"Error") | H22: =SUM(F179:I179)+J250 | I22: =E22+F22-G22-H22 | J22: =E179 | K22: =J22-I22 | L22: =+'MERMAS S1'!D23 | N22: =IF(K22<0,K22*L22,0)
D23: Plateada | F23: =E234 | G23: =IFERROR(SUMPRODUCT(($F$66:$F$153=D23)*$E$66:$E$153*$G$66:$G$153),"Error") | H23: =SUM(F181:I181) | I23: =E23+F23-G23-H23 | J23: =E181 | K23: =J23-I23 | L23: =+'MERMAS S1'!D24 | N23: =IF(K23<0,K23*L23,0)
D24: Pulpo | F24: =E235 | G24: =IFERROR(SUMPRODUCT(($F$66:$F$153=D24)*$E$66:$E$153*$G$66:$G$153),"Error") | H24: =SUM(F182:I182) | I24: =E24+F24-G24-H24 | J24: =E182 | K24: =J24-I24 | L24: =+'MERMAS S1'!D25 | N24: =IF(K24<0,K24*L24,0)
D25: Ragout Lasagna | F25: =H255 | G25: =E257 | H25: =SUM(F183:I183)+J257 | I25: =E25+F25-G25-H25 | J25: =E183 | K25: =J25-I25 | L25: =+'MERMAS S1'!D26 | N25: =IF(K25<0,K25*L25,0)
D26: Ragout Rigatoni | F26: =H256 | G26: =E133 | H26: =SUM(F184:I184) | I26: =E26+F26-G26-H26 | J26: =E184 | K26: =J26-I26 | L26: =+'MERMAS S1'!D27 | N26: =IF(K26<0,K26*L26,0)
D27: Reineta | F27: =E251 | G27: =IFERROR(SUMPRODUCT(($F$66:$F$153=D27)*$E$66:$E$153*$G$66:$G$153),"Error") | H27: =SUM(F163:I163)+J251 | I27: =E27+F27-G27-H27 | J27: =E163 | K27: =J27-I27 | L27: =+'MERMAS S1'!D28 | N27: =IF(K27<0,K27*L27,0)
D28: Salmón ahumado en frío | F28: =E258 | G28: =K258 | H28: =J258 | I28: =E28+F28-G28-H28 | J28: =E185 | K28: =J28-I28 | L28: =+'MERMAS S1'!D29 | N28: =IF(K28<0,K28*L28,0)
D29: Salmón ahumado en Caliente | F29: =E237 | G29: =IFERROR(SUMPRODUCT(($F$66:$F$153=D29)*$E$66:$E$153*$G$66:$G$153),"Error") | H29: =SUM(F186:I186) | I29: =E29+F29-G29-H29 | J29: =E186 | K29: =J29-I29 | L29: =+'MERMAS S1'!D30 | N29: =IF(K29<0,K29*L29,0)
D30: Salmón cancato | F30: =E238 | G30: =IFERROR(SUMPRODUCT(($F$66:$F$153=D30)*$E$66:$E$153*$G$66:$G$153),"Error") | H30: =SUM(F187:I187) | I30: =E30+F30-G30-H30 | J30: =E187 | K30: =J30-I30 | L30: =+'MERMAS S1'!D31 | N30: =IF(K30<0,K30*L30,0)
D31: Salmón fresco premium | F31: =E239 | G31: =IFERROR(SUMPRODUCT(($F$66:$F$153=D31)*$E$66:$E$153*$G$66:$G$153),"Error") | H31: =SUM(F188:I188) | I31: =E31+F31-G31-H31 | J31: =E188 | K31: =J31-I31 | L31: =+'MERMAS S1'!D32 | N31: =IF(K31<0,K31*L31,0)
I33: DIFERENCIAS PROMEDIO | K33: =SUM(K7:K31) | M33: DCTO. TOTAL | N33: =SUM(N7:N31)
F35: + | G35: (-) | H35: (-) | I35: = | J35: = | K35: = | L35: $ | N35: $
D36: PRODUCTOS | F36: Entregas | G36: Ventas | H36: Mermas | I36: Stock Real | J36: Stock Informado | K36: Diferencias | L36: Precio | N36: Descuento
D37: Brownie Nutella | F37: =E264 | G37: =IFERROR(SUMPRODUCT(($F$66:$F$153=D37)*$E$66:$E$153*$G$66:$G$153),"Error") | H37: =SUM(F194:I194) | I37: =E37+F37-G37-H37 | J37: =E194 | K37: =J37-I37 | L37: =+'MERMAS S1'!D33 | N37: =IF(K37<0,K37*L37,0)
D38: Brownie Vegano | F38: =E265 | G38: =IFERROR(SUMPRODUCT(($F$66:$F$153=D38)*$E$66:$E$153*$G$66:$G$153),"Error") | H38: =SUM(F195:I195) | I38: =E38+F38-G38-H38 | J38: =E195 | K38: =J38-I38 | L38: =+'MERMAS S1'!D34 | N38: =IF(K38<0,K38*L38,0)
D39: Cheesecake de Berries | F39: =E262 | G39: =IFERROR(SUMPRODUCT(($F$66:$F$153="Cheesecake Berries")*$E$66:$E$153*$G$66:$G$153),"Error") | H39: =SUM(F196:I196) | I39: =E39+F39-G39-H39 | J39: =E196 | K39: =J39-I39 | L39: =+'MERMAS S1'!D35 | N39: =IF(K39<0,K39*L39,0)
D40: Cheesecake de Limón | F40: =E263 | G40: =IFERROR(SUMPRODUCT(($F$66:$F$153=D40)*$E$66:$E$153*$G$66:$G$153),"Error") | H40: =SUM(F197:H197) | I40: =E40+F40-G40-H40 | J40: =E197 | K40: =J40-I40 | L40: =+'MERMAS S1'!D36 | N40: =IF(K40<0,K40*L40,0)
D41: Chocolate Blanco | F41: =H262 | G41: =J262 | H41: =SUM(F198:I198) | I41: =E41+F41-G41-H41 | J41: =E198 | K41: =J41-I41 | L41: =+'MERMAS S1'!D37 | N41: =IF(K41<0,K41*L41,0)
D42: Chocolate Leche | F42: =H263 | G42: =J263 | H42: =SUM(F199:I199) | I42: =E42+F42-G42-H42 | J42: =E199 | K42: =J42-I42 | L42: =+'MERMAS S1'!D38 | N42: =IF(K42<0,K42*L42,0)
D43: Chocolate Negro | F43: =H264 | G43: =J264 | H43: =SUM(F200:I200) | I43: =E43+F43-G43-H43 | J43: =E200 | K43: =J43-I43 | L43: =+'MERMAS S1'!D39 | N43: =IF(K43<0,K43*L43,0)
...

Sheet S1 Domingo
D2: PRODUCTOS | E2: + | F2: + | G2: (-) | H2: (-) | I2: = | J2: = | K2: = | L2: $ | N2: $
E3: Stock Inicial | F3: Entregas | G3: Ventas | H3: Mermas | I3: Stock Real | J3: Stock Informado | K3: Diferencias | L3: Precio | N3: Descuento
D4: Atún Steak | F4: =E221 | G4: =IFERROR(SUMPRODUCT(($F$66:$F$153="Atún Steak")*$E$66:$E$153*$G$66:$G$153),"Error") | H4: =SUM(F159:J159) | I4: =E4+F4-G4-H4 | J4: =E159 | K4: =J4-I4 | L4: =+'MERMAS S1'!D5 | N4: =IF(K4<0,K4*L4,0)
D5: Atún Trozos | F5: =E222 | G5: =IFERROR(SUMPRODUCT(($F$66:$F$153="Atún Trozos")*$E$66:$E$153*$G$66:$G$153),"Error") | H5: =SUM(F160:I160)+SUM(F190:I190) | I5: =E5+F5-G5-H5 | J5: =E160+E190 | K5: =J5-I5 | L5: =+'MERMAS S1'!D6 | N5: =IF(K5<0,K5*L5,0)
D6: Almejas Julianas | F6: =E254 | G6: =K254 | H6: =SUM(F161:I161)+J254 | I6: =E6+F6-G6-H6 | J6: =E161 | K6: =J6-I6 | L6: =+'MERMAS S1'!D7 | N6: =IF(K6<0,K6*L6,0)
D7: Carpaccio de res | F7: =E223 | G7: =IFERROR(SUMPRODUCT(($F$66:$F$153="Carpaccio de res")*$E$66:$E$153*$G$66:$G$153),"Error") | H7: =SUM(F162:I162) | I7: =E7+F7-G7-H7 | J7: =E162 | K7: =J7-I7 | L7: =+'MERMAS S1'!D8 | N7: =IF(K7<0,K7*L7,0)
D8: Chupe | F8: =H258 | G8: =E90 | H8: =SUM(F165:I165) | I8: =E8+F8-G8-H8 | J8: =E165 | K8: =J8-I8 | L8: =+'MERMAS S1'!D9 | N8: =IF(K8<0,K8*L8,0)
D9: Congrio | F9: =E252 | G9: =IFERROR(SUMPRODUCT(($F$66:$F$153="Congrio")*$E$66:$E$153*$G$66:$G$153),"Error") | H9: =J252+SUM(F164:I164) | I9: =E9+F9-G9-H9 | J9: =E164 | K9: =J9-I9 | L9: =+'MERMAS S1'!D10 | N9: =IF(K9<0,K9*L9,0)
D10: Filete despunte | F10: =E255 | G10: =K255+K256 | H10: =SUM(J255:J256)+SUM(F167:I167) | I10: =E10+F10-G10-H10 | J10: =E167 | K10: =J10-I10 | L10: =+'MERMAS S1'!D11 | N10: =IF(K10<0,K10*L10,0)
D11: Filete para churrasco | F11: =E226 | G11: =IFERROR(SUMPRODUCT(($F$66:$F$153="Filete para churrasco")*$E$66:$E$153*$G$66:$G$153),"Error") | H11: =SUM(F168:I168) | I11: =E11+F11-G11-H11 | J11: =E168 | K11: =J11-I11 | L11: =+'MERMAS S1'!D12 | N11: =IF(K11<0,K11*L11,0)
D12: Filete para crudo | F12: =E227 | G12: =IFERROR(SUMPRODUCT(($F$66:$F$153="Filete para crudo")*$E$66:$E$153*$G$66:$G$153),"Error") | H12: =SUM(F169:I169)+SUM(F189:I189) | I12: =E12+F12-G12-H12 | J12: =E169 +IFERROR(INDEX($E$159:$E$215,MATCH("Tartar de Res",$D$159:$D$215,0)),0) | K12: =J12-I12 | L12: =+'MERMAS S1'!D13 | N12: =IF(K12<0,K12*L12,0)
D13: Filete Salteado | F13: =E228 | G13: =IFERROR(SUMPRODUCT(($F$66:$F$153=D13)*$E$66:$E$153*$G$66:$G$153),"Error") | H13: =SUM(F170:I170) | I13: =E13+F13-G13-H13 | J13: =E170 | K13: =J13-I13 | L13: =+'MERMAS S1'!D14 | N13: =IF(K13<0,K13*L13,0)
D14: Ganso | F14: =E229 | G14: =IFERROR(SUMPRODUCT(($F$66:$F$153=D14)*$E$66:$E$153*$G$66:$G$153),"Error") | H14: =SUM(F171:I171)+SUM(F180:I180) | I14: =E14+F14-G14-H14 | J14: =E171 +IFERROR(INDEX($E$159:$E$215,MATCH("Paila de Carne",$D$159:$D$215,0)),0) | K14: =J14-I14 | L14: =+'MERMAS S1'!D15 | N14: =IF(K14<0,K14*L14,0)
D15: Hamburguesas | F15: =E231 | G15: =IFERROR(SUMPRODUCT(($F$66:$F$153=D15)*$E$66:$E$153*$G$66:$G$153),"Error") | H15: =SUM(F172:I172) | I15: =E15+F15-G15-H15 | J15: =E172 | K15: =J15-I15 | L15: =+'MERMAS S1'!D16 | N15: =IF(K15<0,K15*L15,0)
D16: Jamón serrano | F16: =E232 | G16: =IFERROR(SUMPRODUCT(($F$66:$F$153=D16)*$E$66:$E$153*$G$66:$G$153),"Error") | H16: =SUM(F174:I174) | I16: =E16+F16-G16-H16 | J16: =E174 | K16: =J16-I16 | L16: =+'MERMAS S1'!D17 | N16: =IF(K16<0,K16*L16,0)
D17: Langostinos | F17: =H248 | G17: =IFERROR(SUMPRODUCT(($F$66:$F$153=D17)*$E$66:$E$153*$G$66:$G$153),"Error") | H17: =SUM(F173:I173) | I17: =E17+F17-G17-H17 | J17: =E173 | K17: =J17-I17 | L17: =+'MERMAS S1'!D18 | N17: =IF(K17<0,K17*L17,0)
D18: Lasagna de Berenjenas | F18: =H257 | G18: =E120 | H18: =SUM(F175:I175) | I18: =E18+F18-G18-H18 | J18: =E175 | K18: =J18-I18 | L18: =+'MERMAS S1'!D19 | N18: =IF(K18<0,K18*L18,0)
D19: Locos | F19: =E249 | G19: =IFERROR(SUMPRODUCT(($F$66:$F$153=D19)*$E$66:$E$153*$G$66:$G$153),"Error") | H19: =SUM(F177:I177)+J249 | I19: =E19+F19-G19-H19 | J19: =E177 | K19: =J19-I19 | L19: =+'MERMAS S1'!D20 | N19: =IF(K19<0,K19*L19,0)
D20: Lomo liso | F20: =E233 | G20: =IFERROR(SUMPRODUCT(($F$66:$F$153=D20)*$E$66:$E$153*$G$66:$G$153),"Error") | H20: =SUM(F176:I176) | I20: =E20+F20-G20-H20 | J20: =E176 | K20: =J20-I20 | L20: =+'MERMAS S1'!D21 | N20: =IF(K20<0,K20*L20,0)
D21: Mejillones | F21: =E253 | G21: =K253 | H21: =J253+SUM(F178:I178) | I21: =E21+F21-G21-H21 | J21: =E178 | K21: =J21-I21 | L21: =+'MERMAS S1'!D22 | N21: =IF(K21<0,K21*L21,0)
D22: Merluza | F22: =E250 | G22: =IFERROR(SUMPRODUCT(($F$66:$F$153=D22)*$E$66:$E$153*$G$66:$G$153),"Error") | H22: =SUM(F179:I179)+J250 | I22: =E22+F22-G22-H22 | J22: =E179 | K22: =J22-I22 | L22: =+'MERMAS S1'!D23 | N22: =IF(K22<0,K22*L22,0)
D23: Plateada | F23: =E234 | G23: =IFERROR(SUMPRODUCT(($F$66:$F$153=D23)*$E$66:$E$153*$G$66:$G$153),"Error") | H23: =SUM(F181:I181) | I23: =E23+F23-G23-H23 | J23: =E181 | K23: =J23-I23 | L23: =+'MERMAS S1'!D24 | N23: =IF(K23<0,K23*L23,0)
D24: Pulpo | F24: =E235 | G24: =IFERROR(SUMPRODUCT(($F$66:$F$153=D24)*$E$66:$E$153*$G$66:$G$153),"Error") | H24: =SUM(F182:I182) | I24: =E24+F24-G24-H24 | J24: =E182 | K24: =J24-I24 | L24: =+'MERMAS S1'!D25 | N24: =IF(K24<0,K24*L24,0)
D25: Ragout Lasagna | F25: =H255 | G25: =E257 | H25: =SUM(F183:I183)+J257 | I25: =E25+F25-G25-H25 | J25: =E183 | K25: =J25-I25 | L25: =+'MERMAS S1'!D26 | N25: =IF(K25<0,K25*L25,0)
D26: Ragout Rigatoni | F26: =H256 | G26: =E133 | H26: =SUM(F184:I184) | I26: =E26+F26-G26-H26 | J26: =E184 | K26: =J26-I26 | L26: =+'MERMAS S1'!D27 | N26: =IF(K26<0,K26*L26,0)
D27: Reineta | F27: =E251 | G27: =IFERROR(SUMPRODUCT(($F$66:$F$153=D27)*$E$66:$E$153*$G$66:$G$153),"Error") | H27: =SUM(F163:I163)+J251 | I27: =E27+F27-G27-H27 | J27: =E163 | K27: =J27-I27 | L27: =+'MERMAS S1'!D28 | N27: =IF(K27<0,K27*L27,0)
D28: Salmón ahumado en frío | F28: =E258 | G28: =K258 | H28: =J258 | I28: =E28+F28-G28-H28 | J28: =E185 | K28: =J28-I28 | L28: =+'MERMAS S1'!D29 | N28: =IF(K28<0,K28*L28,0)
D29: Salmón ahumado en Caliente | F29: =E237 | G29: =IFERROR(SUMPRODUCT(($F$66:$F$153=D29)*$E$66:$E$153*$G$66:$G$153),"Error") | H29: =SUM(F186:I186) | I29: =E29+F29-G29-H29 | J29: =E186 | K29: =J29-I29 | L29: =+'MERMAS S1'!D30 | N29: =IF(K29<0,K29*L29,0)
D30: Salmón cancato | F30: =E238 | G30: =IFERROR(SUMPRODUCT(($F$66:$F$153=D30)*$E$66:$E$153*$G$66:$G$153),"Error") | H30: =SUM(F187:I187) | I30: =E30+F30-G30-H30 | J30: =E187 | K30: =J30-I30 | L30: =+'MERMAS S1'!D31 | N30: =IF(K30<0,K30*L30,0)
D31: Salmón fresco premium | F31: =E239 | G31: =IFERROR(SUMPRODUCT(($F$66:$F$153=D31)*$E$66:$E$153*$G$66:$G$153),"Error") | H31: =SUM(F188:I188) | I31: =E31+F31-G31-H31 | J31: =E188 | K31: =J31-I31 | L31: =+'MERMAS S1'!D32 | N31: =IF(K31<0,K31*L31,0)
I33: DIFERENCIAS PROMEDIO | K33: =SUM(K7:K31) | M33: DCTO. TOTAL | N33: =SUM(N7:N31)
F35: + | G35: (-) | H35: (-) | I35: = | J35: = | K35: = | L35: $ | N35: $
D36: PRODUCTOS | F36: Entregas | G36: Ventas | H36: Mermas | I36: Stock Real | J36: Stock Informado | K36: Diferencias | L36: Precio | N36: Descuento
D37: Brownie Nutella | F37: =E264 | G37: =IFERROR(SUMPRODUCT(($F$66:$F$153=D37)*$E$66:$E$153*$G$66:$G$153),"Error") | H37: =SUM(F194:I194) | I37: =E37+F37-G37-H37 | J37: =E194 | K37: =J37-I37 | L37: =+'MERMAS S1'!D33 | N37: =IF(K37<0,K37*L37,0)
D38: Brownie Vegano | F38: =E265 | G38: =IFERROR(SUMPRODUCT(($F$66:$F$153=D38)*$E$66:$E$153*$G$66:$G$153),"Error") | H38: =SUM(F195:I195) | I38: =E38+F38-G38-H38 | J38: =E195 | K38: =J38-I38 | L38: =+'MERMAS S1'!D34 | N38: =IF(K38<0,K38*L38,0)
D39: Cheesecake de Berries | F39: =E262 | G39: =IFERROR(SUMPRODUCT(($F$66:$F$153="Cheesecake Berries")*$E$66:$E$153*$G$66:$G$153),"Error") | H39: =SUM(F196:I196) | I39: =E39+F39-G39-H39 | J39: =E196 | K39: =J39-I39 | L39: =+'MERMAS S1'!D35 | N39: =IF(K39<0,K39*L39,0)
D40: Cheesecake de Limón | F40: =E263 | G40: =IFERROR(SUMPRODUCT(($F$66:$F$153=D40)*$E$66:$E$153*$G$66:$G$153),"Error") | H40: =SUM(F197:H197) | I40: =E40+F40-G40-H40 | J40: =E197 | K40: =J40-I40 | L40: =+'MERMAS S1'!D36 | N40: =IF(K40<0,K40*L40,0)
D41: Chocolate Blanco | F41: =H262 | G41: =J262 | H41: =SUM(F198:I198) | I41: =E41+F41-G41-H41 | J41: =E198 | K41: =J41-I41 | L41: =+'MERMAS S1'!D37 | N41: =IF(K41<0,K41*L41,0)
D42: Chocolate Leche | F42: =H263 | G42: =J263 | H42: =SUM(F199:I199) | I42: =E42+F42-G42-H42 | J42: =E199 | K42: =J42-I42 | L42: =+'MERMAS S1'!D38 | N42: =IF(K42<0,K42*L42,0)
D43: Chocolate Negro | F43: =H264 | G43: =J264 | H43: =SUM(F200:I200) | I43: =E43+F43-G43-H43 | J43: =E200 | K43: =J43-I43 | L43: =+'MERMAS S1'!D39 | N43: =IF(K43<0,K43*L43,0)
...

Sheet MERMAS S1
B3: PRODUCTOS | C3: TOTAL DIFERENCIA | D3: PRECIO | E3: TOTAL DSCTO
